Workbook

Sheet 등록현황
F2: 병원당 최소 1020개 이상 리뷰 등록
A3: 1열 | B3: 목표 등록 수량 | C3: 어드민 등록 수량 | D3: 잔여 수량 | E3: 리뷰 등록 병원 | F3: 리뷰 등록 필요 병원
A4: *눈* | B4: =COUNTIFS('어드민 등록 병원 DB'!O:O, A4, '어드민 등록 병원 DB'!M:M, "O")+COUNTIFS('어드민 등록 병원 DB'!O:O,A4,#REF!,"△ 추가 예정") -> #VALUE! | C4: =COUNTIFS('어드민 등록 병원 DB'!O:O, A4, '어드민 등록 병원 DB'!F:F, "O") -> 18 | D4: =B4-C4 -> #VALUE! | E4: =COUNTIFS('어드민 등록 병원 DB'!O:O, A4, #REF!, "<>") -> #VALUE! | F4: =B4-E4 -> #VALUE!
A5: *코* | B5: =COUNTIFS('어드민 등록 병원 DB'!O:O, A5, #REF!, "O")+COUNTIFS('어드민 등록 병원 DB'!O:O,A5,#REF!,"△ 추가 예정") -> #VALUE! | C5: =COUNTIFS('어드민 등록 병원 DB'!O:O, A5, '어드민 등록 병원 DB'!F:F, "O") -> 13 | D5: =B5-C5 -> #VALUE! | E5: =COUNTIFS('어드민 등록 병원 DB'!O:O, A5, #REF!, "<>") -> #VALUE! | F5: =B5-E5 -> #VALUE!
A6: *안면윤곽* | B6: =COUNTIFS('어드민 등록 병원 DB'!O:O, A6, #REF!, "O")+COUNTIFS('어드민 등록 병원 DB'!O:O,A6,#REF!,"△ 추가 예정") -> #VALUE! | C6: =COUNTIFS('어드민 등록 병원 DB'!O:O, A6, '어드민 등록 병원 DB'!F:F, "O") -> 12 | D6: =B6-C6 -> #VALUE! | E6: =COUNTIFS('어드민 등록 병원 DB'!O:O, A6, #REF!, "<>") -> #VALUE! | F6: =B6-E6 -> #VALUE!
A7: *가슴* | B7: =COUNTIFS('어드민 등록 병원 DB'!O:O, A7, #REF!, "O")+COUNTIFS('어드민 등록 병원 DB'!O:O,A7,#REF!,"△ 추가 예정") -> #VALUE! | C7: =COUNTIFS('어드민 등록 병원 DB'!O:O, A7, '어드민 등록 병원 DB'!F:F, "O") -> 12 | D7: =B7-C7 -> #VALUE! | E7: =COUNTIFS('어드민 등록 병원 DB'!O:O, A7, #REF!, "<>") -> #VALUE! | F7: =B7-E7 -> #VALUE!
A8: *지방성형* | B8: =COUNTIFS('어드민 등록 병원 DB'!O:O, A8, #REF!, "O")+COUNTIFS('어드민 등록 병원 DB'!O:O,A8,#REF!,"△ 추가 예정") -> #VALUE! | C8: =COUNTIFS('어드민 등록 병원 DB'!O:O, A8, '어드민 등록 병원 DB'!F:F, "O") -> 0 | D8: =B8-C8 -> #VALUE! | E8: =COUNTIFS('어드민 등록 병원 DB'!O:O, A8, #REF!, "<>") -> #VALUE! | F8: =B8-E8 -> #VALUE!
A9: *모발이식* | B9: =COUNTIFS('어드민 등록 병원 DB'!O:O, A9, #REF!, "O")+COUNTIFS('어드민 등록 병원 DB'!O:O,A9,#REF!,"△ 추가 예정") -> #VALUE! | C9: =COUNTIFS('어드민 등록 병원 DB'!O:O, A9, '어드민 등록 병원 DB'!F:F, "O") -> 12 | D9: =B9-C9 -> #VALUE! | E9: =COUNTIFS('어드민 등록 병원 DB'!O:O, A9, #REF!, "<>") -> #VALUE! | F9: =B9-E9 -> #VALUE!
A10: *피부과* | B10: =COUNTIFS('어드민 등록 병원 DB'!O:O, A10, #REF!, "O")+COUNTIFS('어드민 등록 병원 DB'!O:O,A10,#REF!,"△ 추가 예정") -> #VALUE! | C10: =COUNTIFS('어드민 등록 병원 DB'!O:O, A10, '어드민 등록 병원 DB'!F:F, "O") -> 18 | D10: =B10-C10 -> #VALUE! | E10: =COUNTIFS('어드민 등록 병원 DB'!O:O, A10, #REF!, "<>") -> #VALUE! | F10: =B10-E10 -> #VALUE!
A11: *리프팅* | B11: =COUNTIFS('어드민 등록 병원 DB'!O:O, A11, #REF!, "O")+COUNTIFS('어드민 등록 병원 DB'!O:O,A11,#REF!,"△ 추가 예정") -> #VALUE! | C11: =COUNTIFS('어드민 등록 병원 DB'!O:O, A11, '어드민 등록 병원 DB'!F:F, "O") -> 7 | D11: =B11-C11 -> #VALUE! | E11: =COUNTIFS('어드민 등록 병원 DB'!O:O, A11, #REF!, "<>") -> #VALUE! | F11: =B11-E11 -> #VALUE!
A12: *줄기세포* | B12: =COUNTIFS('어드민 등록 병원 DB'!O:O, A12, #REF!, "O")+COUNTIFS('어드민 등록 병원 DB'!O:O,A12,#REF!,"△ 추가 예정") -> #VALUE! | C12: =COUNTIFS('어드민 등록 병원 DB'!O:O, A12, '어드민 등록 병원 DB'!F:F, "O") -> 6 | D12: =B12-C12 -> #VALUE! | E12: =COUNTIFS('어드민 등록 병원 DB'!O:O, A12, #REF!, "<>") -> #VALUE! | F12: =B12-E12 -> #VALUE! | H12: *벤셀의원 리뷰 없음
B13: =SUM(카테고리별_병원_등록_진행상황[목표 등록 수량]) -> #VALUE! | C13: =SUM(카테고리별_병원_등록_진행상황[어드민 등록 수량]) -> 98 | D13: =SUM(카테고리별_병원_등록_진행상황[잔여 수량]) -> #VALUE! | E13: =SUM(카테고리별_병원_등록_진행상황[리뷰 등록 병원]) -> #VALUE! | F13: =SUM(카테고리별_병원_등록_진행상황[리뷰 등록 필요 병원]) -> #VALUE!
A17: 의료진 등록 현황
A18: 전체 병원 수 | B18: =counta(D26:D104) -> 79 | C18: 진행속도: | D18: =B21/B18 -> 1
A19: 의료진 조사된 병원 수 | B19: =countif(E26:E104, ">0") -> 79 | C19: 준비속도: | D19: =B19/B18 -> 1
A20: 의료진 조사 필요 병원 수 | B20: =B18-B19 -> 0
A21: (어드민) 등록된 병원수 | B21: =countif(F26:F104, ">0") -> 79
A22: (어드민) 등록 필요 병원수 | B22: =B18-B21 -> 0
A24: 의료진 등록 상황 (총 수) | D24: 병원별 의료진 등록 상황 | I24: 진료과목/병원별 의료진 등록 상황
A25: 의료진 수 (데이터) | B25: 어드민 등록 수 | D25: 병원명 | E25: 의료진 수 (데이터) | F25: 어드민 등록 수 | G25: 어드민 등록 필요 | I25: 진료과목 | J25: 병원명 | K25: 의료진 수 (데이터) | L25: 어드민 등록 수 | M25: 어드민 등록 필요
A26: 213 | B26: 213 | D26: 강남 리슬림의원 | E26: 1 | F26: 1 | G26: =E26-F26 -> 0 | I26: 가슴 총계 | K26: 24 | L26: 24 | M26: =K26-L26 -> 0
D27: 강남로미모의원 | E27: 3 | F27: 3 | G27: =E27-F27 -> 0 | I27: 눈 | J27: 노상훈성형외과의원 | K27: 3 | L27: 3 | M27: =K27-L27 -> 0
D28: 기린성형외과의원 | E28: 2 | F28: 2 | G28: =E28-F28 -> 0 | J28: 땡큐성형외과의원 | K28: 3 | L28: 3 | M28: =K28-L28 -> 0
D29: 나나성형외과의원 | E29: 5 | F29: 5 | G29: =E29-F29 -> 0 | J29: 루비성형외과의원 | K29: 3 | L29: 3 | M29: =K29-L29 -> 0
D30: 노상훈성형외과의원 | E30: 3 | F30: 3 | G30: =E30-F30 -> 0 | J30: 마블성형외과의원 | K30: 3 | L30: 3 | M30: =K30-L30 -> 0
D31: 노트성형외과의원 | E31: 2 | F31: 2 | G31: =E31-F31 -> 0 | J31: 미호성형외과의원 | K31: 3 | L31: 3 | M31: =K31-L31 -> 0
D32: 더난성형외과의원 | E32: 1 | F32: 1 | G32: =E32-F32 -> 0 | J32: 아이큐성형외과의원 | K32: 1 | L32: 1 | M32: =K32-L32 -> 0
D33: 더도어성형외과의원 | E33: 4 | F33: 4 | G33: =E33-F33 -> 0 | J33: 아이팅성형외과의원 | K33: 3 | L33: 3 | M33: =K33-L33 -> 0
D34: 더새로이의원 | E34: 2 | F34: 2 | G34: =E34-F34 -> 0 | J34: 옐로우성형외과의원 | K34: 2 | L34: 2 | M34: =K34-L34 -> 0
D35: 데이뷰의원 강남점 | E35: 5 | F35: 5 | G35: =E35-F35 -> 0 | J35: 일미리성형외과의원 | K35: 4 | L35: 4 | M35: =K35-L35 -> 0
D36: 디에이성형외과의원 | E36: 4 | F36: 4 | G36: =E36-F36 -> 0 | J36: 자연주의성형외과의원 | K36: 4 | L36: 4 | M36: =K36-L36 -> 0
D37: 땡큐성형외과의원 | E37: 3 | F37: 3 | G37: =E37-F37 -> 0 | J37: 제이티성형외과의원 | K37: 3 | L37: 3 | M37: =K37-L37 -> 0
D38: 라비앙성형외과의원 | E38: 4 | F38: 4 | G38: =E38-F38 -> 0 | J38: 처음처럼성형외과의원 | K38: 1 | L38: 1 | M38: =K38-L38 -> 0
D39: 레디성형외과의원 | E39: 1 | F39: 1 | G39: =E39-F39 -> 0 | J39: 티에스성형외과의원 | K39: 5 | L39: 5 | M39: =K39-L39 -> 0
D40: 레스트의원 | E40: 1 | F40: 1 | G40: =E40-F40 -> 0 | J40: 팝성형외과의원 | K40: 5 | L40: 5 | M40: =K40-L40 -> 0
D41: 레아트성형외과의원 | E41: 3 | F41: 3 | G41: =E41-F41 -> 0 | I41: 눈 총계 | K41: 43 | L41: 43 | M41: =K41-L41 -> 0
D42: 로이셀의원 | E42: 1 | F42: 1 | G42: =E42-F42 -> 0 | I42: 눈, 코 | J42: 에이비성형외과의원 | K42: 5 | L42: 5 | M42: =K42-L42 -> 0
D43: 루비성형외과의원 | E43: 3 | F43: 3 | G43: =E43-F43 -> 0 | I43: 눈, 코 총계 | K43: 5 | L43: 5 | M43: =K43-L43 -> 0
D44: 르메디크의원 | E44: 1 | F44: 1 | G44: =E44-F44 -> 0 | I44: 리프팅 | J44: 리팅성형외과의원 | K44: 5 | L44: 5 | M44: =K44-L44 -> 0
D45: 리뉴얼의원 | E45: 1 | F45: 1 | G45: =E45-F45 -> 0 | J45: 압구정미라클의원 | K45: 2 | L45: 2 | M45: =K45-L45 -> 0
...

Sheet 병원 리스트
A1: 병원명 | B1: 시술부위 | C1: 상세 시술/부위 | D1: 계약진행여부 | E1: 정보성 영상 | F1: 리얼후기 영상 | G1: 기타 영상 | H1: 노출 희망 영상 | J1: 병원 단체톡방 여부 | K1: 병원명 | L1: 1. 모델 이미지 | M1: 2. 병원 로고 파일(ai 또는 svg) | N1: 3. 의료진 관련 자료 | O1: 4. 후기 콘텐츠 자료 | P1: 5. 영상 자료 | Q1: 6. 병원 기본 정보 | R1: 7. K-DOC 전용 소통 채널 정보 | S1: 8. 시술 상세 페이지 제작용 자료 | T1: 9. 상담 매뉴얼 | U1: 10. 원내 이미지 | V1: 11. 해외 수가표
A2: 압구정미라클의원 | B2: 리프팅 | D2: 계약완료 | J2: 있음 | K2: 압구정미라클의원 | L2: 완료 | M2: 완료 | N2: 완료 | O2: 완료 | P2: 완료 | Q2: 완료 | R2: 완료 | S2: 완료 | T2: 완료 | U2: 완료 | V2: 진행중 | W2: 압구정미라클의원 | X2: 1. 고화질 보정 모델 이미지 2. 병원 로고 파일(ai 또는 svg 형식) 3. 의료진 관련 자료 · 의사 성명 및 영문명 · 의사 프로필 사진 4. 후기 콘텐츠 자료 · 메인 리뷰에 등록될 사진 · 리뷰용 사진 · 실제 후기 내용 텍스트 5. 영상 자료 · 노출 희망 유튜브 영상 링크 · 병원 자체 제작 영상(홍보 영상 등) 6. 병원 기본 정보 · 병원 대표 연락처 및 이메일 · 기타 연락 가능 채널 7. K-DOC 전용 소통 채널 정보 · 담당자 연락처 및 이메일 · 기타 실시간 커뮤니케이션 수단 8. 시술 상세 페이지 제작용 자료 · 시술 설명 텍스트 · 시술 과정 또는 결과 이미지 9. 상담 매뉴얼 · 내원 고객 상담 프로세스 · 상담 단계별 안내 기준 · 시술별 상담 포인트(주의사항, 권장 대상 등) · 상담 시 사용되는 자료 또는 가이드 · 상담실 담당자 연락 가능 시간 및 운영 방식 10. 원내 이미지 11. 해외 수가표
A3: 스마일러치과의원 | B3: 치과 | D3: 알수없음 | E3: https://www.youtube.com/watch?v=T-2x8qS6p8o | F3: X | G3: X | J3: 없음 | K3: 스마일러치과의원 | L3: 진행중 | M3: 진행중 | N3: 진행중 | O3: 진행중 | P3: 진행중 | Q3: 진행중 | R3: 진행중 | S3: 진행중 | T3: 진행중 | U3: 진행중 | V3: 완료 | W3: 스마일러치과의원
A4: 청담비포앤애프터클리닉 | B4: 피부과, 줄기세포, 기타 | D4: 알수없음 | E4: X | F4: X | G4: https://www.youtube.com/watch?v=DYGMHha5oyw | J4: 있음 | K4: 청담비포앤애프터클리닉 | L4: 진행중 | M4: 진행중 | N4: 진행중 | O4: 진행중 | P4: 진행중 | Q4: 진행중 | R4: 진행중 | S4: 진행중 | T4: 진행중 | U4: 진행중 | V4: 진행중 | W4: 청담비포앤애프터클리닉
A5: 닥터송포유의원 | B5: 리프팅 | D5: 알수없음 | E5: https://www.youtube.com/watch?v=RR2VEjmQAsc | F5: https://www.youtube.com/watch?v=dqLfZ2fQ_RU | G5: https://www.youtube.com/watch?v=ZxJrhdtysi4 | J5: 있음 | K5: 닥터송포유의원 | L5: 진행중 | M5: 진행중 | N5: 진행중 | O5: 진행중 | P5: 완료 | Q5: 진행중 | R5: 진행중 | S5: 진행중 | T5: 진행중 | U5: 진행중 | V5: 완료 | W5: 닥터송포유의원
A6: 봉봉성형외과의원 | B6: 가슴 | D6: 알수없음 | E6: https://www.youtube.com/watch?v=PfBdpnBOksc | F6: https://www.youtube.com/watch?v=5ekUXoIDG0M | G6: https://www.youtube.com/watch?v=Is7cJi_Kq4A | J6: 있음 | K6: 봉봉성형외과의원 | L6: 진행중 | M6: 진행중 | N6: 진행중 | O6: 진행중 | P6: 진행중 | Q6: 진행중 | R6: 진행중 | S6: 진행중 | T6: 진행중 | U6: 진행중 | V6: 완료 | W6: 봉봉성형외과의원
A7: V&MJ피부과의원 | B7: 리프팅 | D7: 알수없음 | E7: https://www.youtube.com/watch?v=YsbeqK5wm28 | F7: https://www.youtube.com/watch?v=fGOqiNpRUag | G7: https://www.youtube.com/watch?v=_pUfix-VjB8 | J7: 있음 | K7: V&MJ피부과의원 | L7: 완료 | M7: 완료 | N7: 완료 | O7: 완료 | P7: 완료 | Q7: 완료 | R7: 완료 | S7: 완료 | T7: 완료 | U7: 진행중 | V7: 진행중 | W7: V&MJ피부과의원
A8: 땡큐성형외과의원 | B8: 눈, 코, 기타 | D8: 알수없음 | E8: https://www.youtube.com/watch?v=FiPty5_kKgM&t=127s | F8: https://www.youtube.com/watch?v=oL90EMMpb1o | G8: https://www.youtube.com/watch?v=Gc6SVoPgEQo | J8: 없음 | K8: 땡큐성형외과의원 | L8: 진행중 | M8: 진행중 | N8: 진행중 | O8: 진행중 | P8: 진행중 | Q8: 진행중 | R8: 진행중 | S8: 진행중 | T8: 진행중 | U8: 진행중 | V8: 완료 | W8: 땡큐성형외과의원
A9: 연세다인성형외과의원 | B9: 눈, 리프팅 | D9: 알수없음 | E9: https://www.youtube.com/watch?v=a6kzinTXG04 | F9: https://www.youtube.com/watch?v=bYlJ_kg132k | G9: https://www.youtube.com/watch?v=yMiRFMJPujM | J9: 없음 | K9: 연세다인성형외과의원 | L9: 진행중 | M9: 진행중 | N9: 진행중 | O9: 진행중 | P9: 진행중 | Q9: 진행중 | R9: 진행중 | S9: 진행중 | T9: 진행중 | U9: 진행중 | V9: 진행중 | W9: 연세다인성형외과의원
A10: 허쉬성형외과의원 | B10: 바디 | C10: 바디필러 | D10: 알수없음 | E10: https://www.youtube.com/watch?v=daF6ei8EUDU | F10: https://www.youtube.com/watch?v=pZ7zhLO_5Ng | G10: https://www.youtube.com/watch?v=-IQ8cn1_H0w | J10: 있음 | K10: 허쉬성형외과의원 | L10: 진행중 | M10: 진행중 | N10: 진행중 | O10: 진행중 | P10: 진행중 | Q10: 진행중 | R10: 진행중 | S10: 진행중 | T10: 진행중 | U10: 진행중 | V10: 진행중 | W10: 허쉬성형외과의원
A11: 플랜에스의원 | B11: 바디 | C11: 다이어트 | D11: 알수없음 | E11: https://www.youtube.com/watch?v=hPb1LKv0MAE | F11: X | G11: https://www.youtube.com/watch?v=kkjvWYDjp3o | J11: 없음 | K11: 플랜에스의원 | L11: 진행중 | M11: 진행중 | N11: 진행중 | O11: 진행중 | P11: 진행중 | Q11: 진행중 | R11: 진행중 | S11: 진행중 | T11: 진행중 | U11: 진행중 | V11: 진행중 | W11: 플랜에스의원
A12: 일퍼센트성형외과의원 | B12: 안면윤곽, 기타 | D12: 알수없음 | E12: https://www.youtube.com/watch?v=gc5IklsNHhI | F12: https://www.youtube.com/watch?v=vgZ5L-nIObE | G12: https://www.youtube.com/watch?v=OL_QN9hKbCU | J12: 있음 | K12: 일퍼센트성형외과의원 | L12: 진행중 | M12: 완료 | N12: 완료 | O12: 완료 | P12: 완료 | Q12: 진행중 | R12: 진행중 | S12: 진행중 | T12: 진행중 | U12: 완료 | V12: 진행중 | W12: 일퍼센트성형외과의원
A13: 슈가성형외과의원 | B13: 눈 | D13: 알수없음 | E13: https://www.youtube.com/watch?v=1dKyQIntmRg | F13: https://www.youtube.com/watch?v=IeymOQ_ocnU | G13: https://www.youtube.com/watch?v=8BGLBgTiMy4 | J13: 있음 | K13: 슈가성형외과의원 | L13: 진행중 | M13: 진행중 | N13: 진행중 | O13: 진행중 | P13: 진행중 | Q13: 진행중 | R13: 진행중 | S13: 진행중 | T13: 진행중 | U13: 진행중 | V13: 진행중 | W13: 슈가성형외과의원
A14: 피그마리온의원 | B14: 리프팅 | D14: 알수없음 | E14: https://youtu.be/odJSJmd7DAs?si=9cAYqm-k87TaaERh | F14: https://youtu.be/AcUr3ZOf80w?si=JTNfi56qYDQ97_fxx | G14: https://youtu.be/mkDHAnvAWH0?si=UjddDx52rpJEvtyG | J14: 없음 | K14: 피그마리온의원 | L14: 진행중 | M14: 진행중 | N14: 진행중 | O14: 진행중 | P14: 진행중 | Q14: 진행중 | R14: 진행중 | S14: 진행중 | T14: 진행중 | U14: 진행중 | V14: 진행중 | W14: 피그마리온의원
A15: 마인드성형외과의원 | B15: 눈, 코, 기타 | D15: 계약완료 | E15: https://youtu.be/KqsyznaR8-Q?si=TR3xdQOeYBV_l7v9 | F15: https://youtu.be/2AgHi7v9Kxk?si=6ycssXl92R2z0qLX | G15: https://youtu.be/uOpehT1gJo8?si=XFCf-k8fccYZGGTj | J15: 있음 | K15: 마인드성형외과의원 | L15: 진행중 | M15: 진행중 | N15: 진행중 | O15: 진행중 | P15: 진행중 | Q15: 진행중 | R15: 진행중 | S15: 진행중 | T15: 진행중 | U15: 진행중 | V15: 진행중 | W15: 마인드성형외과의원
A16: 클래스원의원 | B16: 피부과 | D16: 알수없음 | E16: https://youtu.be/cdFqNfFROtc?si=2vKUW8HDvbgq4zbA | F16: https://youtu.be/hKkw1AsIFzs?si=_DtV5MDDsiXtqld3 | G16: https://youtu.be/5lk371PZN4I?si=HjWhVJjytOx8bmMD | J16: 없음 | K16: 클래스원의원 | L16: 진행중 | M16: 진행중 | N16: 진행중 | O16: 진행중 | P16: 진행중 | Q16: 진행중 | R16: 진행중 | S16: 진행중 | T16: 진행중 | U16: 진행중 | V16: 진행중 | W16: 클래스원의원
A17: 247클리닉 | B17: 바디 | C17: 바디필러 | D17: 알수없음 | E17: https://youtu.be/eRuHTloJC1o?si=XVaxUfwYs_ajkL5V | F17: https://youtu.be/rYLNjRvsNJE?si=rwRXv8E8O118Cd5X | G17: https://youtu.be/oL8PmxViq3E?si=7IvlcTKLFHbnuT0Z | J17: 없음 | K17: 247클리닉 | L17: 진행중 | M17: 진행중 | N17: 진행중 | O17: 진행중 | P17: 진행중 | Q17: 진행중 | R17: 진행중 | S17: 진행중 | T17: 진행중 | U17: 진행중 | V17: 완료 | W17: 247클리닉
A18: 디캐럿의원 | B18: 피부과 | D18: 알수없음 | E18: https://youtu.be/CB3h6aKPbAE?si=z_ZRf5TLixYi4FmZ | F18: https://youtu.be/dc5DIXm6vZk?si=Hn2ct5c5gzEytW0R | G18: https://youtu.be/bKrOa8gjB4I?si=Brxkt298Eecox_TP | J18: 없음 | K18: 디캐럿의원 | L18: 진행중 | M18: 진행중 | N18: 진행중 | O18: 진행중 | P18: 진행중 | Q18: 진행중 | R18: 진행중 | S18: 진행중 | T18: 진행중 | U18: 진행중 | V18: 진행중 | W18: 디캐럿의원
A19: 제로원성형외과의원 | B19: 리프팅 | D19: 알수없음 | E19: https://youtu.be/KHf0t_pWye8?si=AEacgmsIFxoy5Xpy | F19: https://youtu.be/87szGr7wTRs?si=3w5cM1jVvNwYQ1m6 | G19: https://youtu.be/1QAp01lEkGw?si=fpafegYXamBBJSiU | J19: 없음 | K19: 제로원성형외과의원 | L19: 진행중 | M19: 진행중 | N19: 진행중 | O19: 진행중 | P19: 진행중 | Q19: 진행중 | R19: 진행중 | S19: 진행중 | T19: 진행중 | U19: 진행중 | V19: 진행중 | W19: 제로원성형외과의원
A20: RU성형외과의원 | B20: 코, 안면윤곽 | D20: 알수없음 | E20: https://youtu.be/cCnPypkEePs?si=9fBm6aknu39LQYEU | F20: https://youtu.be/A_FW-Cy8CMc?si=JToQk1kLqNCa2RgR | G20: https://youtu.be/ZvZAXTS60t8?si=jTM_iXAgUeXDakIf | J20: 없음 | K20: RU성형외과의원 | L20: 진행중 | M20: 진행중 | N20: 진행중 | O20: 진행중 | P20: 진행중 | Q20: 진행중 | R20: 진행중 | S20: 진행중 | T20: 진행중 | U20: 진행중 | V20: 진행중 | W20: RU성형외과의원
A21: 에이블룸성형외과의원 | B21: 피부과 | D21: 계약완료 | E21: https://youtu.be/gbNYJ-_sxG4?si=WHuUB1kSxZgAf0x4 | F21: https://youtu.be/QufGPgvcvUw?si=hxUBifEnCd4AIdu5 | G21: https://youtu.be/i_VK3gXtcXk?si=IO94-5rYPUw35hLB | J21: 있음 | K21: 에이블룸성형외과의원 | L21: 진행중 | M21: 완료 | N21: 진행중 | O21: 완료 | P21: 완료 | Q21: 완료 | R21: 완료 | S21: 진행중 | T21: 진행중 | U21: 완료 | V21: 진행중 | W21: 에이블룸성형외과의원
A22: 셀린의원 강남역 | B22: 피부과 | D22: 알수없음 | E22: https://youtu.be/tr4DrqpoYaQ?si=O7whePrcLPhBucxO | F22: https://youtu.be/UVBv8eqYsuY?si=S7zB8yzg8M5apBQH | G22: https://youtu.be/mnxwuhG3-wc?si=m-oLzuq8oY5J1QPa | J22: 없음 | K22: 셀린의원 강남역 | L22: 진행중 | M22: 진행중 | N22: 진행중 | O22: 진행중 | P22: 진행중 | Q22: 진행중 | R22: 진행중 | S22: 진행중 | T22: 진행중 | U22: 진행중 | V22: 진행중 | W22: 셀린의원 강남역
A23: 르에이치의원 | B23: 피부과 | D23: 알수없음 | E23: https://youtu.be/V_n2oNirCzQ?si=1zy2fadXbl5z6fG4 | F23: https://youtu.be/UPRaTZVuUo0?si=V0o3HLEK9M8jqXH6 | G23: https://youtu.be/Gm2m5n74XeU?si=-PuRO8UCbB9olAtm | H23: https://youtu.be/Gm2m5n74XeU?si=AeUc2tLI9amE50JQ | J23: 있음 | K23: 르에이치의원 | L23: 진행중 | M23: 완료 | N23: 완료 | O23: 완료 | P23: 진행중 | Q23: 완료 | R23: 완료 | S23: 완료 | T23: 진행중 | U23: 완료 | V23: 진행중 | W23: 르에이치의원
A24: 다미의원 | B24: 피부과 | D24: 알수없음 | E24: https://www.youtube.com/watch?v=U_o7iA0jo2c | F24: X | G24: X | J24: 없음 | K24: 다미의원 | L24: 진행중 | M24: 진행중 | N24: 진행중 | O24: 진행중 | P24: 진행중 | Q24: 진행중 | R24: 진행중 | S24: 진행중 | T24: 진행중 | U24: 진행중 | V24: 진행중 | W24: 다미의원
A25: 이즈의원 | B25: 피부과 | D25: 알수없음 | E25: X | F25: X | G25: https://youtu.be/UY7IREHoMe0?si=D6cA6NjLIvWjLim_ | J25: 없음 | K25: 이즈의원 | L25: 진행중 | M25: 진행중 | N25: 진행중 | O25: 진행중 | P25: 진행중 | Q25: 진행중 | R25: 진행중 | S25: 진행중 | T25: 진행중 | U25: 진행중 | V25: 진행중 | W25: 이즈의원
A26: 서래선치과의원 | B26: 치과 | D26: 알수없음 | E26: https://youtu.be/D2-mnlRs5B0?si=vptbVwaShTDHLTBE | F26: https://youtu.be/OPalgKxfq84?si=aOlGQmPnlj79lQid | G26: https://youtu.be/dIp-EX7Sl-w?si=Y_b8unFGVo2XC1tB | J26: 없음 | K26: 서래선치과의원 | L26: 진행중 | M26: 진행중 | N26: 진행중 | O26: 진행중 | P26: 진행중 | Q26: 진행중 | R26: 진행중 | S26: 진행중 | T26: 진행중 | U26: 진행중 | V26: 진행중 | W26: 서래선치과의원
A27: 서울페이스21치과병원 | B27: 안면윤곽, 치과 | D27: 알수없음 | E27: https://youtu.be/xZq4KGQlzpg?si=twYoushIks730_Pz | F27: https://youtu.be/hKkw1AsIFzs?si=_DtV5MDDsiXtqld3 | G27: https://youtu.be/kXhPDKY3nIc?si=9-22GpgpIo5jZeFg | J27: 없음 | K27: 서울페이스21치과병원 | L27: 진행중 | M27: 진행중 | N27: 진행중 | O27: 진행중 | P27: 진행중 | Q27: 진행중 | R27: 진행중 | S27: 진행중 | T27: 진행중 | U27: 진행중 | V27: 진행중 | W27: 서울페이스21치과병원
A28: 미니쉬치과병원 | B28: 치과 | D28: 계약완료 | E28: https://youtu.be/4NVzeMp8_BY?si=mWYfUG92ztCaWh2f | F28: https://youtu.be/JMLqfMYUlYQ?si=8HM7LAG1qHhxmOf8 | G28: https://youtu.be/rzApdsvS1IU?si=ut9IKa8HRLs9148e | J28: 있음 | K28: 미니쉬치과병원 | L28: 진행중 | M28: 진행중 | N28: 진행중 | O28: 진행중 | P28: 진행중 | Q28: 진행중 | R28: 진행중 | S28: 진행중 | T28: 진행중 | U28: 진행중 | V28: 진행중 | W28: 미니쉬치과병원
A29: 모앤라인성형외과의원 | B29: 모발이식 | D29: 논의중 | E29: https://www.youtube.com/watch?v=Xy_OeS_QJ-Q | F29: https://www.youtube.com/watch?v=6yU7OwYjSys | G29: https://www.youtube.com/watch?v=eokK8lwB_uQ | J29: 있음 | K29: 모앤라인성형외과의원 | L29: 진행중 | M29: 진행중 | N29: 진행중 | O29: 진행중 | P29: 진행중 | Q29: 진행중 | R29: 진행중 | S29: 진행중 | T29: 진행중 | U29: 진행중 | V29: 진행중 | W29: 모앤라인성형외과의원
A30: 지우개의원 | B30: 바디 | D30: 알수없음 | E30: https://www.youtube.com/watch?v=LPArdypj29w | F30: https://www.youtube.com/watch?v=dasf8kjBSVA | G30: https://www.youtube.com/watch?v=f442FF4Zh7c | J30: 있음 | K30: 지우개의원 | L30: 진행중 | M30: 완료 | N30: 진행중 | O30: 완료 | P30: 진행중 | Q30: 완료 | R30: 완료 | S30: 진행중 | T30: 완료 | U30: 완료 | V30: 진행중 | W30: 지우개의원
A31: 멜론성형외과의원 | B31: 가슴 | D31: 알수없음 | E31: https://www.youtube.com/watch?v=bOtTGJZe1kQ | F31: https://www.youtube.com/watch?v=dXtlvyGc_UY | G31: https://www.youtube.com/watch?v=LkzAIJRyfxo | J31: 있음 | K31: 멜론성형외과의원 | L31: 진행중 | M31: 진행중 | N31: 진행중 | O31: 완료 | P31: 완료 | Q31: 진행중 | R31: 진행중 | S31: 진행중 | T31: 진행중 | U31: 완료 | V31: 완료 | W31: 멜론성형외과의원
A32: 아이루미성형외과의원 | B32: 안면윤곽, 눈 | C32: 양악/침샘수술 | D32: 알수없음 | J32: 있음 | K32: 아이루미성형외과의원 | L32: 완료 | M32: 완료 | N32: 완료 | O32: 완료 | P32: 완료 | Q32: 진행중 | R32: 진행중 | S32: 진행중 | T32: 진행중 | U32: 진행중 | V32: 진행중 | W32: 아이루미성형외과의원
A33: 스노우의원 | B33: 지방흡입 | D33: 계약완료 | J33: 없음 | K33: 스노우의원 | L33: 진행중 | M33: 진행중 | N33: 진행중 | O33: 진행중 | P33: 진행중 | Q33: 진행중 | R33: 진행중 | S33: 진행중 | T33: 진행중 | U33: 진행중 | V33: 진행중 | W33: 스노우의원
B34: ※아래서부턴 계약 X 병원※
A35: 바람부는날에도성형외과의원 | B35: 모발이식 | C35: 이마축소 | D35: 계약해지 | E35: https://www.youtube.com/watch?v=draxfv6x9Cs | F35: https://www.youtube.com/watch?v=aD9XnKLrRvA | G35: https://www.youtube.com/watch?v=0cXtkdVLj8U
A36: 어나더성형외과의원 | B36: 코, 기타 | D36: 계약해지 | E36: https://youtu.be/2_uSN5cAwCU?si=YBe4JYxjvb1avgkS | F36: https://youtu.be/rXe_m0maSqk?si=DwETLshG12c-P6X3 | G36: https://youtu.be/S34XXQd982o?si=AzNTTW1JQpl7L2UW
A37: 티에스성형외과의원 | B37: 눈
A38: 일미리성형외과의원 | B38: 눈
A39: 팝성형외과의원 | B39: 눈
A40: 마블성형외과의원 | B40: 눈
...

Sheet 시트35
B1: @도준님 링크 들어가서 문서에 병원 / 시술별로 정리하면 됩니다. 그리고 병원별 해외 수가표 누르면 해당 드라이브로 연결되는 것처럼 시술별로 링크 설정해두면 됩니다. https://docs.google.com/document/d/1QlFcQpL3Ca_LYu3MbtZpyegPlGknB8unYGJomuBDUI8/edit?usp=sharing
E9: 병원 실제 시술 항목
A10: 병원명 | B10: K-DOC 시술부위 | C10: K-DOC 상세 시술/부위 | D10: 대분류 | E10: 홈페이지 대분류 | F10: 홈페이지 중분류 | G10: 홈페이지 중분류 | H10: 홈페이지 중분류 | I10: 홈페이지 중분류 | J10: 홈페이지 중분류 | K10: 홈페이지 중분류 | L10: 홈페이지 중분류 | M10: 홈페이지 중분류 | N10: 홈페이지 중분류 | O10: 홈페이지 중분류 | P10: 홈페이지 중분류
A11: 압구정미라클의원 | B11: 리프팅 | E11: 리프팅 | F11: 실리프팅
A12: 스마일러치과의원 | B12: 치과 | C12: 치과 | E12: 임플란트 | F12: 당일 임플란트 | G12: 가이드 임플란트 | H12: 임플란트 보철(지르코니아)
E13: 보철치료
E14: 심미치료
E15: 보존치료
E16: 치아교정
A17: 청담비포앤애프터클리닉 | B17: 피부과, 줄기세포, 기타
A18: 닥터송포유의원 | B18: 리프팅
A19: 봉봉성형외과의원 | B19: 가슴
A20: V&MJ피부과의원 | B20: 리프팅
A21: 땡큐성형외과의원 | B21: 눈, 코, 기타
A22: 연세다인성형외과의원 | B22: 눈, 리프팅
A23: 허쉬성형외과의원 | B23: 바디 | C23: 바디필러
A24: 플랜에스의원 | B24: 바디 | C24: 다이어트
A25: 일퍼센트성형외과의원 | B25: 안면윤곽, 기타
A26: 슈가성형외과의원 | B26: 눈
A27: 피그마리온의원 | B27: 리프팅
A28: 마인드성형외과의원 | B28: 눈, 코, 기타
A29: 클래스원의원 | B29: 피부과
A30: 247클리닉 | B30: 바디 | C30: 바디필러
A31: 디캐럿의원 | B31: 피부과
A32: 제로원성형외과의원 | B32: 리프팅 | D32: 눈 | E32: 눈성형 | F32: 자연유착 | G32: 절개 | H32: 눈매교정 | I32: 트임 | J32: 눈밑지방 | K32: 눈재수술
D33: 코 | E33: 코성형 | F33: 기능코 | G33: 유형별 코수술
D34: 코 | E34: 특수코 재건술 | F34: 외상 후 코성형 | G34: 구축코 재건술 | H34: 콧구멍 수술 | I34: 재수술
D35: 윤곽 | E35: 커스텀핏 윤곽조각술 | F35: 윤곽조각술 | G35: 이중턱 박멸술
D36: 안티에이징 | E36: 안티에이징 | F36: 안면거상술 미니거상술 | G36: 실리프팅 | H36: 항노화주사
D37: 바디 | E37: 바디성형 | F37: 힙업 지방이식 | G37: 지방흡입
D38: 가슴 | E38: 가슴성형 | F38: 가슴 축소술 | G38: 유두 유룬 성형 | H38: 남성 여유증
D39: 쁘띠 | E39: 쁘띠성형 | F39: V라인주사&S라인주사 | G39: 필러 | H39: 보톡스
A45: RU성형외과의원 | B45: 코, 안면윤곽
A46: 에이블룸성형외과의원 | B46: 피부과 | D46: 리프팅 | E46: 리프팅 | F46: 악센트 프라임 튠 | G46: 울쎄라 | H46: 써마지 FLX | I46: 소프라노 티타늄 | J46: 실리프팅
D47: 피부 | E47: 콜라겐 스티뮬레이터 | F47: 스컬트라 | G47: 바디 스컬트라 | H47: 엘란쎄
D48: 피부 | E48: 스킨부스터 | F48: 에이블 스킨부스터 | G48: 리쥬란 | H48: 쥬베룩 | I48: 리투오 콜라겐 스킨부스터
D49: 쁘띠 | E49: 볼륨 필러 | F49: 히알루론산 필러
D50: 쁘띠 | E50: 초음파 보톡스 | F50: 초음파 보톡스 | G50: 초음파 바디 보톡스 | H50: 브이올렛 | I50: 초음파 윤곽주사
D51: 피부 | E51: 피부 | F51: 소프라노 티타늄 | G51: 커스텀 스킨케어 | H51: 에이블 스킨부스터 | I51: 모공흉터 치료 | J51: 색소 치료 | K51: 여드름트러블케어 | L51: 레이저 제모
A52: 셀린의원 강남역 | B52: 피부과
...

Sheet 시트37
D1: 병원 실제 시술 항목
A2: 병원명 | B2: K-DOC 시술부위 | C2: K-DOC 상세 시술/부위 | D2: 홈페이지 대분류 | E2: 홈페이지 중분류 | F2: 홈페이지 중분류 | G2: 홈페이지 중분류 | H2: 홈페이지 중분류 | I2: 홈페이지 중분류 | J2: 홈페이지 중분류 | K2: 홈페이지 중분류 | L2: 홈페이지 중분류 | M2: 홈페이지 중분류 | N2: 홈페이지 중분류 | O2: 홈페이지 중분류
A3: 제로원성형외과의원 | B3: 리프팅 | D3: 눈성형 | E3: 자연유착 | F3: 절개 | G3: 눈매교정 | H3: 트임 | I3: 눈밑지방 | J3: 눈재수술
D4: 코성형 | E4: 기능코 | F4: 유형별 코수술
D5: 특수코 재건술 | E5: 외상 후 코성형 | F5: 구축코 재건술 | G5: 콧구멍 수술 | H5: 재수술
D6: 커스텀핏 윤곽조각술 | E6: 윤곽조각술 | F6: 이중턱 박멸술
D7: 안티에이징 | E7: 안면거상술 미니거상술 | F7: 실리프팅 | G7: 항노화주사
D8: 바디성형 | E8: 힙업 지방이식 | F8: 지방흡입
D9: 가슴성형 | E9: 가슴 축소술 | F9: 유두 유룬 성형 | G9: 남성 여유증
D10: 쁘띠성형 | E10: V라인주사&S라인주사 | F10: 필러 | G10: 보톡스

Sheet 병원 리스트(표 형식)
B2: BEST = ※백지원 지사장님 PICK병원 Or 계약된 병원※ | E2: 백지원 지사징님이 제외 요청한 병원
A5: 순위 | B5: 눈 | C5: 코 | D5: 안면윤곽 | E5: 가슴 | F5: 지방흡입 | G5: 바디 | H5: 모발이식 | I5: 피부과 | J5: 리프팅 | K5: 줄기세포 | L5: 치과
A6: 1 | B6: 슈가성형외과의원 | C6: 땡큐성형외과의원 | D6: 일퍼센트성형외과의원 | E6: 봉봉성형외과의원 | F6: 초이스라인의원 | G6: 허쉬성형외과의원 | H6: 바람부는날에도성형외과의원 | I6: 청담비포앤애프터클리닉 | J6: 압구정미라클의원 | K6: 셀리크의원 | L6: 서울페이스21치과병원
A7: 2 | B7: 티에스성형외과의원 | C7: 마인드성형외과의원 | D7: 아이루미성형외과의원 | E7: 라비앙성형외과의원 | F7: 에이탑성형외과의원 | G7: 247클리닉 | H7: 모제림성형외과의원 | I7: 클래스원의원 | J7: 연세다인성형외과의원 | K7: 청담쥬넥스 피부과의원 | L7: 스마일러치과의원
A8: 3 | B8: 일미리성형외과의원 | C8: 에이비성형외과의원 | D8: 본디성형외과의원 | E8: 뷰성형외과의원 | F8: 레디성형외과의원 | G8: 플랜에스의원 | H8: 옥건헤어라인의원 | I8: 디캐럿의원 | J8: 닥터송포유의원 | K8: 르메디크의원 | L8: 서래선치과의원
A9: 4 | B9: 팝성형외과의원 | C9: 어나더성형외과의원 | D9: 우리성형외과의원 | E9: 엠디외과의원 | F9: 기린성형외과의원 | G9: 지우개의원 | H9: 모앤블레스의원 | I9: 에이블룸성형외과의원 | J9: V&MJ피부과의원 | K9: 티알 트리니티 라파엘로 청담의원 | L9: 미니쉬치과병원
A10: 5 | B10: 마블성형외과의원 | C10: 프라이빗성형외과의원 | D10: 브라운성형외과의원 | E10: 노트성형외과의원 | F10: G7클리닉 | H10: 서울아이성형외과의원 | I10: 셀린의원 강남역 | J10: 피그마리온의원 | K10: 밴셀의원
A11: 6 | B11: 옐로우성형외과의원 | C11: 더도어성형외과의원 | D11: 이유구강악안면외과치과의원 | E11: 에이트성형외과의원 | F11: 뽐나게빼의원 | H11: 강남로미모의원 | I11: 르에이치의원 | J11: 제로원성형외과의원 | K11: 청담비포앤애프터클리닉
A12: 7 | B12: 노상훈성형외과의원 | C12: 위버스성형외과의원 | D12: 새김성형외과의원 | E12: UBA성형외과의원 | F12: 스노우의원 | H12: 모든모의원 | I12: 다미의원 | J12: 리팅성형외과의원
A13: 8 | B13: 루비성형외과의원 | C13: 디에이성형외과의원 | D13: 타코성형외과의원 | E13: 물방울성형외과의원 | F13: 더새로이의원 | H13: 서진성형외과의원 | I13: 이즈의원
A14: 9 | B14: 자연주의성형외과의원 | C14: 더난성형외과의원 | D14: 오페라성형외과의원 | E14: 오케이성형외과 | F14: 강남 리슬림의원 | H14: 모우림의원 | I14: 모즈의원
A15: 10 | B15: 처음처럼성형외과의원 | C15: 첫단추의원 | D15: 아이디병원 | E15: 아이디병원 | F15: 레아트성형외과의원 | H15: 모디헤어플란트의원 | I15: 리뉴얼의원
A16: 11 | B16: 미호성형외과의원 | C16: 히트성형외과의원 | D16: 서울페이스21치과병원 | E16: 나나성형외과의원 | H16: 모플러스성형외과의원 | I16: 청담서클의원
A17: 12 | B17: 제이티성형외과의원 | C17: 나나성형외과의원 | D17: RU성형외과의원 | E17: 멜론성형외과의원 | H17: 모앤라인성형외과의원 | I17: 엠레드의원
A18: 13 | B18: 아이팅성형외과의원 | C18: RU성형외과의원 | I18: 연세YB의원
A19: 14 | B19: 아이큐성형외과의원 | I19: 데이뷰의원 강남점
A20: 15 | B20: 연세다인성형외과의원 | I20: 문의원
A21: 16 | B21: 땡큐성형외과의원 | I21: 레스트의원
A22: 17 | B22: 마인드성형외과의원 | I22: 로이셀의원
A23: 18 | B23: 에이비성형외과의원 | I23: 허준원M.D.피부과의원
A24: 19

Sheet 배지(최종)_251211
A2: 영역 | B2: 눈 | C2: 코 | D2: 안면윤곽 | E2: 가슴 | F2: 지방흡입 | G2: 바디 | H2: 모발이식 | I2: 피부과 | J2: 리프팅 | K2: 줄기세포 | L2: 치과 | M2: 기타
A3: BEST | B3: 땡큐성형외과의원 | C3: 땡큐성형외과의원 | D3: 일퍼센트성형외과의원 | E3: 봉봉성형외과의원 | F3: 기린성형외과의원 | G3: 허쉬성형외과의원 | H3: 모앤라인 | I3: 청담비포앤애프터클리닉 | J3: 압구정미라클의원 | K3: 청담비포앤애프터클리닉 | L3: 미니쉬치과병원 | M3: 청담비포앤애프터클리닉
B4: 마인드성형외과의원 | C4: 마인드성형외과의원 | F4: 초이스라인의원 | I4: 르에이치의원 | M4: 땡큐성형외과의원
M5: 마인드성형외과의원
M6: 일퍼센트성형외과의원
M7: 어나더성형외과의원
A11: HOT | B11: 연세다인성형외과의원 | C11: RU성형외과의원 | D11: 브라운성형외과의원 | E11: 아이디병원 | F11: 에이탑성형외과의원 | G11: 247클리닉 | H11: 바람부는날에도성형외과의원 | I11: 클래스원의원 | J11: 피그마리온의원 | K11: 밴셀의원 | L11: 서울페이스21치과병원
B12: 슈가성형외과의원 | C12: 디에이성형외과의원 | D12: 아이디병원 | E12: 라비앙성형외과의원 | F12: 강남 리슬림의원 | G12: 플랜에스의원 | I12: 디캐럿의원 | J12: 닥터송포유의원 | L12: 스마일러치과의원
B13: 팝성형외과의원 | I13: 에이블룸성형외과의원 | L13: 서래선치과의원
I14: 셀린의원 강남역
A18: 추천 | B18: 압구정미라클의원 | C18: 리프팅 | D18: BEST | E18: 1
B19: 미니쉬치과병원 | C19: 치과 | D19: BEST | E19: 2
B20: 일퍼센트성형외과의원 | C20: 안면윤곽 | D20: BEST | E20: 3
B21: 청담비포앤애프터클리닉 | C21: 줄기세포 | D21: BEST | E21: 4
B22: 봉봉성형외과의원 | C22: 가슴 | D22: BEST | E22: 5
B23: 허쉬성형외과의원 | C23: 바디 | D23: BEST | E23: 6
B24: 땡큐성형외과의원 | C24: 눈 | D24: BEST | E24: 7
B25: 마인드성형외과의원 | C25: 코 | D25: BEST | E25: 8
B26: 초이스라인의원 | C26: 지방흡입 | D26: BEST | E26: 9
B27: 모앤라인 | C27: 모발이식 | D27: BEST | E27: 10
B28: 르에이치의원 | C28: 피부과과 | D28: BEST | E28: 11
B29: 디에이성형외과의원 | C29: 코코 | D29: HOT | E29: 12
B35: 노란색은 운영에 반영되었습니다.

Sheet 어드민 등록 병원 DB
A2: N | B2: 계약 완료 | C2: 랭킹 | D2: 평점 | E2: 리뷰 자동화 개수 | F2: 어드민 등록 | G2: 상세(대표사진) | H2: 상세(내부사진) | I2: 실시간 생생 후기 이미지 | J2: 유튜브 링크 | K2: 병원 내부 사진 드라이브 업로드 | L2: 썸네일 | M2: 의료진 수 (자료 조사) | N2: 의료진 수 (어드민 등록) | O2: 진료과목 (노션기준) | P2: KR | Q2: EN | R2: TH | S2: address-KR (동까지만) | T2: address-EN | U2: address-TH | V2: 위도 | W2: 경도 | X2: directions-KR(상세주소) | Y2: directions-EN | Z2: directions-TH | AA2: directions-IN | AB2: description-KR | AC2: description-EN | AD2: description-TH | AE2: description-IN | AF2: openingHours | AG2: Price-min | AH2: 평점 개수에 가중치 부여 (10개 이하는 0.5배, 100개 이상은 2배, 500개 이상은 5배, 1000개 이상은 10배) | AI2: Price-max | AJ2: 구글 평점(9/24) | AK2: 개수 | AL2: 네이버 평점 | AM2: 개수 | AN2: 카카오 평점 | AO2: 개수 | AP2: 성예사 평점 | AQ2: 개수 | AR2: 성예사 점수 | AS2: 단순평점 | AT2: 평점 개수에 가중치 부여 (10개 이하는 0.5배, 100개 이상은 2배, 500개 이상은 5배, 1000개 이상은 10배) | AU2: discountRate | AV2: approvalStatusType | AW2: rejectReason | AX2: baseId | AY2: hasClone | AZ2: districtId | BA2: createdAt | BB2: updatedAt
A3: 1 | B3: O | C3: 1 | D3: 5 | E3: =SUM( COUNTIF('리뷰 전체 모음 시트'!H:H, P3) ) -> 53 | F3: O | G3: O | H3: O | I3: O | L3: O | M3: =COUNTIFS('의사 등록'!D:D, P3, '의사 등록'!E:E, "<>") -> 2 | N3: =COUNTIFS('의사 등록'!D:D, P3, '의사 등록'!T:T, "<>") -> 2 | O3: 리프팅 | P3: 압구정미라클의원 | Q3: Apgujeong Miracle Clinic | R3: คลินิกอับกูจองมิราเคิล | S3: 서울 강남구 신사동 | T3: Sinsa-dong, Gangnam-gu, Seoul | U3: แขวงซินซา เขตคังนัม กรุงโซล | V3: 37.526145 | W3: 127.03884 | X3: 서울특별시 강남구 선릉로157길 14 한주빌딩 5층, 6층 | Y3: 5F, 14 Seolleung-ro 157-gil, Gangnam-gu, Seoul, 06018, Republic of Korea | Z3: 5F, 14 Seolleung-ro 157-gil, Gangnam-gu, Seoul, 06018, Republic of Korea | AB3: 세계 성형외과의사들이 인정한 실리프팅/재수술/안티에이징/비만체형 | AC3: Recognized by plastic surgeons worldwide for thread lifting, revision surgery, anti-aging, and body contouring. | AD3: เป็นที่ยอมรับในระดับโลกโดยศัลยแพทย์ตกแต่ง สำหรับการร้อยไหม การแก้ศัลยกรรม ความงามชะลอวัย และการปรับรูปร่าง | AF3: {"friday":{"holiday":false,"openTime":"10:00","closeTime":"19:00","monday":{"holiday":false,"openTime":"10:00","closeTime":"19:00","sunday":{"holiday":true,"tuesday":{"holiday":false,"openTime":"10:00","closeTime":"19:00","saturday":{"holiday":false,"openTime":"10:00","closeTime":"17:00","thursday":{"holiday":false,"openTime":"10:00","closeTime":"19:00","wednesday":{"holiday":false,"openTime":"10:00","closeTime":"19:00","launchTime":{"openTime":"","closeTime":"" | AG3: 1500 | AH3: =AT3 -> 0.011 | AJ3: 4.9 | AK3: 38 | AM3: 2821 | AP3: 3.2 | AQ3: 41 | AR3: 62 | AS3: =(AJ3*AK3)+(AL3*AM3)+(AN3*AO3)+(AP3*AQ3)/(AK3+AM3+AO3+AQ3) -> 0.10944828 | AT3: =IF( (AK3*IF(AK3<10,0.5,IF(AK3>=1000,10,IF(AK3>=500,5,IF(AK3>=100,2,1))))) + (AM3*IF(AM3<10,0.5,IF(AM3>=1000,10,IF(AM3>=500,5,IF(AM3>=100,2,1))))) + (AO3*IF(AO3<10,0.5,IF(AO3>=1000,10,IF(AO3>=500,5,IF(AO3>=100,2,1))))) + (AQ3*IF(AQ3<10,0.5,IF(AQ3>=1000,10,IF(AQ3>=500,5,IF(AQ3>=100,2,1))))) =0, "", ROUND( MIN(5, MAX(0, ( AJ3*(AK3*IF(AK3<10,0.5,IF(AK3>=1000,10,IF(AK3>=500,5,IF(AK3>=100,2,1))))) + AL3*(AM3*IF(AM3<10,0.5,IF(AM3>=1000,10,IF(AM3>=500,5,IF(AM3>=100,2,1))))) + AN3*(AO3*IF(AO3<10,0.5,IF(AO3>=1000,10,IF(AO3>=500,5,IF(AO3>=100,2,1))))) + AP3*(AQ3*IF(AQ3<10,0.5,IF(AQ3>=1000,10,IF(AQ3>=500,5,IF(AQ3>=100,2,1))))) ) / ( (AK3*IF(AK3<10,0.5,IF(AK3>=1000,10,IF(AK3>=500,5,IF(AK3>=100,2,1))))) + (AM3*IF(AM3<10,0.5,IF(AM3>=1000,10,IF(AM3>=500,5,IF(AM3>=100,2,1))))) + (AO3*IF(AO3<10,0.5,IF(AO3>=1000,10,IF(AO3>=500,5,IF(AO3>=100,2,1))))) + (AQ3*IF(AQ3<10,0.5,IF(AQ3>=1000,10,IF(AQ3>=500,5,IF(AQ3>=100,2,1))))) ) ) ), 3 ) ) -> 0.011 | AV3: APPROVED | AY3: FALSE | AZ3: c54ce51a-d567-46ba-8f3f-1561a19b562f | BA3: 45719.287 | BB3: 45910.344
A4: 2 | B4: O | C4: 2 | D4: 5 | E4: =SUM( COUNTIF('리뷰 전체 모음 시트'!H:H, P4) ) -> 18 | F4: O | G4: O | H4: O | I4: △ | J4: X | K4: O | L4: O | M4: =COUNTIFS('의사 등록'!D:D, P4, '의사 등록'!E:E, "<>") -> 1 | N4: =COUNTIFS('의사 등록'!D:D, P4, '의사 등록'!T:T, "<>") -> 1 | O4: 치과 | P4: 스마일러치과의원 | Q4: Smilel Dental Clinic | R4: คลินิกทันตกรรมสไมล์ล์ | S4: 서울 송파구 문정동 | T4: Munjeong-dong, Songpa-gu, Seoul | U4: เขตซงพา แขวงมุนจอง กรุงโซล | V4: 37.4894 | W4: 127.12285 | X4: 서울 송파구 동남로 102 레이102빌딩 2층 | Y4: 2F 102 Dongnam-ro, Songpa-gu, Seoul | Z4: 2F 102 Dongnam-ro, Songpa-gu, Seoul | AB4: 스마일러 치과는 3D 안면 스캐너, 3D CT, 구강스캐너, 세라믹 밀링기로 최소삭제 방식을 채택하여, 빠르고 정밀한 라미네이트와 보철 진료를 제공합니다. 또한, 가이드 즉시기능 임플란트로 더욱 빠르고, 안전한 결과를 약속 드립니다. | AC4: Smilel Dental Clinic uses a 3D facial scanner, 3D CT, oral scanner, and ceramic milling machine to apply a minimally invasive technique, providing fast and precise laminate and prosthetic treatments. In addition, we promise faster and safer results with guided immediate-function implants. | AD4: คลินิกทันตกรรมสไมล์ล์ใช้เครื่องสแกนใบหน้าแบบ 3 มิติ, CT 3 มิติ, เครื่องสแกนในช่องปาก และเครื่องกัดเซรามิก เพื่อให้การรักษาลามิเนตและงานฟันเทียมมีความแม่นยำและรวดเร็ว ด้วยเทคนิคการกรอฟันให้น้อยที่สุด นอกจากนี้ เรายังรับประกันผลลัพธ์ที่รวดเร็วและปลอดภัยยิ่งขึ้นด้วยการปลูกฟันเทียมแบบนำวิธีและใช้งานได้ทันที | AF4: 월 09:30 ~ 18:00 화 09:30 ~ 18:00 수 09:30 ~ 18:00 목 09:30 ~ 18:00 금 09:30 ~ 18:00 토 09:30 ~ 14:00 | AG4: 812 | AH4: =AT4 -> 0.109 | AJ4: 0 | AK4: 0 | AM4: 45 | AN4: 5 | AO4: 2 | AP4: 0 | AQ4: 0 | AR4: 0 | AS4: =(AJ4*AK4)+(AL4*AM4)+(AN4*AO4)+(AP4*AQ4)/(AK4+AM4+AO4+AQ4) -> 0.21276596 | AT4: =IF( (AK4*IF(AK4<10,0.5,IF(AK4>=1000,10,IF(AK4>=500,5,IF(AK4>=100,2,1))))) + (AM4*IF(AM4<10,0.5,IF(AM4>=1000,10,IF(AM4>=500,5,IF(AM4>=100,2,1))))) + (AO4*IF(AO4<10,0.5,IF(AO4>=1000,10,IF(AO4>=500,5,IF(AO4>=100,2,1))))) + (AQ4*IF(AQ4<10,0.5,IF(AQ4>=1000,10,IF(AQ4>=500,5,IF(AQ4>=100,2,1))))) =0, "", ROUND( MIN(5, MAX(0, ( AJ4*(AK4*IF(AK4<10,0.5,IF(AK4>=1000,10,IF(AK4>=500,5,IF(AK4>=100,2,1))))) + AL4*(AM4*IF(AM4<10,0.5,IF(AM4>=1000,10,IF(AM4>=500,5,IF(AM4>=100,2,1))))) + AN4*(AO4*IF(AO4<10,0.5,IF(AO4>=1000,10,IF(AO4>=500,5,IF(AO4>=100,2,1))))) + AP4*(AQ4*IF(AQ4<10,0.5,IF(AQ4>=1000,10,IF(AQ4>=500,5,IF(AQ4>=100,2,1))))) ) / ( (AK4*IF(AK4<10,0.5,IF(AK4>=1000,10,IF(AK4>=500,5,IF(AK4>=100,2,1))))) + (AM4*IF(AM4<10,0.5,IF(AM4>=1000,10,IF(AM4>=500,5,IF(AM4>=100,2,1))))) + (AO4*IF(AO4<10,0.5,IF(AO4>=1000,10,IF(AO4>=500,5,IF(AO4>=100,2,1))))) + (AQ4*IF(AQ4<10,0.5,IF(AQ4>=1000,10,IF(AQ4>=500,5,IF(AQ4>=100,2,1))))) ) ) ), 3 ) ) -> 0.109
A5: 3 | B5: O | C5: 3 | D5: 4.9 | E5: =SUM( COUNTIF('리뷰 전체 모음 시트'!H:H, P5) ) -> 25 | F5: O | G5: O | H5: O | I5: △ | J5: X | K5: O | L5: O | M5: =COUNTIFS('의사 등록'!D:D, P5, '의사 등록'!E:E, "<>") -> 1 | N5: =COUNTIFS('의사 등록'!D:D, P5, '의사 등록'!T:T, "<>") -> 1 | O5: 피부과, 줄기세포 | P5: 청담비포앤애프터클리닉 | Q5: Cheongdam Before & After Clinic | R5: Cheongdam Before & After Clinic | S5: 서울 강남구 청담동 | T5: Cheongdam-dong, Gangnam-gu, Seoul | U5: แขวงชองดัม เขตคังนัม กรุงโซล | V5: 37.526972 | W5: 127.04515 | X5: 서울 강남구 청담동 141-13 | Y5: 437 Apgujeong-ro, Gangnam-gu, Seoul | Z5: 437 Apgujeong-ro, Gangnam-gu, Seoul | AB5: 차별화된 서비스와 전문성을 바탕으로 고객 개개인의 변화와 성장을 돕는 것을 목표로 하고 있습니다. 이를 통해 고객의 만족도를 높이고자 하는 것이 비포앤애프터클리닉의 “당신 변화의 첫걸음!”이라는 슬로건의 핵심 메시지 통해 고객의 외모와 건강을 종합적으로 관리하고 개인의 피부, 체형, 건강 상태를 종합적으로 분석하여 맞춤형 관리 솔루션을 제공합니다 | AC5: Based on differentiated services and expertise, we aim to help each client achieve personal transformation and growth. Through this, we strive to enhance customer satisfaction — the core message behind Before & After Clinic’s slogan: “Your First Step to Change!” We provide comprehensive care for beauty and health by analyzing each individual’s skin, body shape, and overall condition to deliver customized treatment solutions. | AD5: ด้วยบริการที่แตกต่างและความเชี่ยวชาญเฉพาะทาง เรามุ่งมั่นที่จะช่วยให้ลูกค้าแต่ละคนได้พัฒนาตัวเองและเปลี่ยนแปลงไปในทางที่ดีขึ้น ซึ่งเป็นสาระสำคัญของสโลแกนของ Before & After Clinic – “ก้าวแรกแห่งการเปลี่ยนแปลงของคุณ!” เราดูแลทั้งรูปลักษณ์และสุขภาพของลูกค้าอย่างครบวงจร โดยวิเคราะห์สภาพผิว รูปร่าง และสุขภาพของแต่ละบุคคล เพื่อมอบโซลูชันการดูแลแบบเฉพาะบุคคลที่เหมาะสมที่สุด | AF5: 월 10:00 ~ 19:00 화 10:00 ~ 19:00 수 10:00 ~ 19:00 목 10:00 ~ 19:00 금 10:00 ~ 20:00 토 10:00 ~ 17:00 | AG5: 가격 명시X (1500) | AH5: =AT5 -> 0.029 | AJ5: 5 | AK5: 17 | AL5: 0 | AM5: 585 | AN5: 0 | AO5: 0 | AP5: 0 | AQ5: 0 | AR5: 0 | AS5: =(AJ5*AK5)+(AL5*AM5)+(AN5*AO5)+(AP5*AQ5)/(AK5+AM5+AO5+AQ5) -> 0.14119601 | AT5: =IF( (AK5*IF(AK5<10,0.5,IF(AK5>=1000,10,IF(AK5>=500,5,IF(AK5>=100,2,1))))) + (AM5*IF(AM5<10,0.5,IF(AM5>=1000,10,IF(AM5>=500,5,IF(AM5>=100,2,1))))) + (AO5*IF(AO5<10,0.5,IF(AO5>=1000,10,IF(AO5>=500,5,IF(AO5>=100,2,1))))) + (AQ5*IF(AQ5<10,0.5,IF(AQ5>=1000,10,IF(AQ5>=500,5,IF(AQ5>=100,2,1))))) =0, "", ROUND( MIN(5, MAX(0, ( AJ5*(AK5*IF(AK5<10,0.5,IF(AK5>=1000,10,IF(AK5>=500,5,IF(AK5>=100,2,1))))) + AL5*(AM5*IF(AM5<10,0.5,IF(AM5>=1000,10,IF(AM5>=500,5,IF(AM5>=100,2,1))))) + AN5*(AO5*IF(AO5<10,0.5,IF(AO5>=1000,10,IF(AO5>=500,5,IF(AO5>=100,2,1))))) + AP5*(AQ5*IF(AQ5<10,0.5,IF(AQ5>=1000,10,IF(AQ5>=500,5,IF(AQ5>=100,2,1))))) ) / ( (AK5*IF(AK5<10,0.5,IF(AK5>=1000,10,IF(AK5>=500,5,IF(AK5>=100,2,1))))) + (AM5*IF(AM5<10,0.5,IF(AM5>=1000,10,IF(AM5>=500,5,IF(AM5>=100,2,1))))) + (AO5*IF(AO5<10,0.5,IF(AO5>=1000,10,IF(AO5>=500,5,IF(AO5>=100,2,1))))) + (AQ5*IF(AQ5<10,0.5,IF(AQ5>=1000,10,IF(AQ5>=500,5,IF(AQ5>=100,2,1))))) ) ) ), 3 ) ) -> 0.029
A6: 4 | B6: O | C6: 5 | D6: 4.7 | E6: =SUM( COUNTIF('리뷰 전체 모음 시트'!H:H, P6) ) -> 3 | F6: O | G6: O | H6: O | I6: △ | J6: O | K6: O | L6: O | M6: =COUNTIFS('의사 등록'!D:D, P6, '의사 등록'!E:E, "<>") -> 1 | N6: =COUNTIFS('의사 등록'!D:D, P6, '의사 등록'!T:T, "<>") -> 1 | O6: 리프팅 | P6: 닥터송포유의원 | Q6: Dr.Song 4u Plastic Surgery | R6: Dr.Song 4u คลินิกศัลยกรรมตกแต่ง | S6: 서울 강남구 역삼동 | T6: Yeoksam-dong, Gangnam-gu, Seoul | U6: แขวงย็อกซัม เขตคังนัม กรุงโซล | V6: 37.508207 | W6: 127.03775 | X6: 서울특별시 강남구 역삼동 653-5 | Y6: 653-5 Yeoksam-dong, Gangnam District, Seoul | Z6: 653-5 Yeoksam-dong, Gangnam District, Seoul | AB6: 안녕하세요, 닥터송포유의원입니다. 개개인의 얼굴형과 이목구비 모양까지 고려한, 체계적인 맞춤 성형으로 누구나 부러워할 외모로 변신해 보세요 :) - 눈/코재수술 - 안면거상 (포니테일 리프팅/하이스마스 안면거상)/ 목거상/ 이마거상/ 가슴거상/ 복부거상 - 이물질제거술 - 가슴성형 | AC6: Hello, this is Dr.Song 4U Plastic Surgery. Transform yourself into a look everyone will admire through our personalized and systematic plastic surgery, designed to match your individual facial structure and features. Eye and nose revision surgery Facelift (Ponytail lifting / High SMAS facelift) / Neck lift / Forehead lift / Breast lift / Abdominoplasty Foreign substance removal surgery Breast augmentation | AD6: สวัสดีค่ะ นี่คือ Dr.Song 4U คลินิกศัลยกรรมตกแต่ง เปลี่ยนแปลงตัวเองให้สวยโดดเด่นจนใคร ๆ ก็ต้องอิจฉา ด้วยศัลยกรรมแบบเฉพาะบุคคลที่ออกแบบอย่างเป็นระบบ โดยคำนึงถึงโครงหน้าและลักษณะใบหน้าของแต่ละคน แก้ตา / แก้จมูก ดึงหน้า (Ponytail lifting / High SMAS) / ดึงคอ / ดึงหน้าผาก / ดึงหน้าอก / ดึงหน้าท้อง ผ่าตัดเอาสารแปลกปลอมออก ศัลยกรรมหน้าอก | AF6: 월 09:30 ~ 18:30 화 09:30 ~ 18:30 수 09:30 ~ 18:30 금 09:30 ~ 18:30 토 09:30 ~ 17:00 | AG6: 10000 | AH6: =AT6 -> 4.4 | AN6: 0 | AO6: 0 | AP6: 4.4 | AQ6: 10 | AR6: 0 | AS6: =(AJ6*AK6)+(AL6*AM6)+(AN6*AO6)+(AP6*AQ6)/(AK6+AM6+AO6+AQ6) -> 4.4 | AT6: =IF( (AK6*IF(AK6<10,0.5,IF(AK6>=1000,10,IF(AK6>=500,5,IF(AK6>=100,2,1))))) + (AM6*IF(AM6<10,0.5,IF(AM6>=1000,10,IF(AM6>=500,5,IF(AM6>=100,2,1))))) + (AO6*IF(AO6<10,0.5,IF(AO6>=1000,10,IF(AO6>=500,5,IF(AO6>=100,2,1))))) + (AQ6*IF(AQ6<10,0.5,IF(AQ6>=1000,10,IF(AQ6>=500,5,IF(AQ6>=100,2,1))))) =0, "", ROUND( MIN(5, MAX(0, ( AJ6*(AK6*IF(AK6<10,0.5,IF(AK6>=1000,10,IF(AK6>=500,5,IF(AK6>=100,2,1))))) + AL6*(AM6*IF(AM6<10,0.5,IF(AM6>=1000,10,IF(AM6>=500,5,IF(AM6>=100,2,1))))) + AN6*(AO6*IF(AO6<10,0.5,IF(AO6>=1000,10,IF(AO6>=500,5,IF(AO6>=100,2,1))))) + AP6*(AQ6*IF(AQ6<10,0.5,IF(AQ6>=1000,10,IF(AQ6>=500,5,IF(AQ6>=100,2,1))))) ) / ( (AK6*IF(AK6<10,0.5,IF(AK6>=1000,10,IF(AK6>=500,5,IF(AK6>=100,2,1))))) + (AM6*IF(AM6<10,0.5,IF(AM6>=1000,10,IF(AM6>=500,5,IF(AM6>=100,2,1))))) + (AO6*IF(AO6<10,0.5,IF(AO6>=1000,10,IF(AO6>=500,5,IF(AO6>=100,2,1))))) + (AQ6*IF(AQ6<10,0.5,IF(AQ6>=1000,10,IF(AQ6>=500,5,IF(AQ6>=100,2,1))))) ) ) ), 3 ) ) -> 4.4
A7: 5 | B7: O | C7: 6 | D7: 4.6 | E7: =SUM( COUNTIF('리뷰 전체 모음 시트'!H:H, P7) ) -> 3 | F7: O | G7: O | H7: O | I7: △ | J7: O | K7: O | L7: O | M7: =COUNTIFS('의사 등록'!D:D, P7, '의사 등록'!E:E, "<>") -> 3 | N7: =COUNTIFS('의사 등록'!D:D, P7, '의사 등록'!T:T, "<>") -> 3 | O7: 가슴 | P7: 봉봉성형외과의원 | Q7: Bong Bong Plastic Surgery | R7: Bong Bong คลินิกศัลยกรรมตกแต่ง | S7: 서울 강남구 논현동 | T7: Nonhyeon-dong, Gangnam-gu, Seoul | U7: แขวงนอนฮยอน เขตคังนัม กรุงโซล | V7: 37.512571 | W7: 127.0311 | X7: 서울 강남구 논현로 657 그린빌딩 | Y7: 657 Nonhyeon-ro, Gangnam-gu, Seoul | Z7: 657 Nonhyeon-ro, Gangnam-gu, Seoul | AB7: 자연주의 성형 미학 봉봉성형외과 환자 중심, 안전 중심의 진료를 바탕으로 수술의 정확성을 높이는 첨단 수술 장비와 무균 수술 시스템, 응급 의료 장치들을 갖추고 있으며, 끊임 없는 연구와 국내외에서 왕성한 학술활동을 통한 숙련도 높은 의료진들의 가슴, 체형,여성성형, 재건 성형 등의 분야에서 완성도 높은 결과를 이끄는 의료 서비스를 확인하실 수 있습니다. 진료 분야: 눈,코, 가슴/힙(보형물, 지방 이식, 필러), 줄기세포, 지방(이식,흡입), 복부성형, 안면 거상, 리프팅, 보형물 및 이물질 제거, 가슴/힙 재수술 | AC7: Bong Bong Plastic Surgery pursues natural aesthetic beauty. With a patient-centered and safety-first approach, we are equipped with advanced surgical equipment, sterile operating systems, and emergency medical facilities to ensure precision and safety. Through continuous research and active participation in domestic and international academic activities, our highly skilled medical team delivers exceptional results in breast surgery, body contouring, female plastic surgery, and reconstructive surgery. Main specialties: Eyes, nose, breast/hip (implants, fat grafting, fillers), stem cells, fat (grafting/liposuction), abdominoplasty, facelift, lifting, implant & foreign substance removal, breast/hip revision surgery | AD7: Bong Bong คลินิกศัลยกรรมตกแต่งมุ่งเน้นความงามแบบธรรมชาติ เราดำเนินการรักษาโดยยึดผู้ป่วยเป็นศูนย์กลางและให้ความสำคัญกับความปลอดภัย พร้อมด้วยอุปกรณ์ศัลยกรรมที่ทันสมัย ระบบผ่าตัดปลอดเชื้อ และเครื่องมือฉุกเฉินครบครัน เพื่อความแม่นยำและความปลอดภัยสูงสุด ด้วยการวิจัยอย่างต่อเนื่องและการเข้าร่วมกิจกรรมทางวิชาการทั้งในและต่างประเทศ ทีมแพทย์ผู้เชี่ยวชาญของเรามีความชำนาญสูงในด้านศัลยกรรมหน้าอก การปรับรูปร่าง ศัลยกรรมผู้หญิง และการศัลยกรรมตกแต่งเพื่อการฟื้นฟู สาขาการรักษาหลัก: ตา จมูก หน้าอก/สะโพก (ซิลิโคน ไขมัน ฟิลเลอร์) เซลล์ต้นกำเนิด ไขมัน (ปลูกถ่าย/ดูดไขมัน) ศัลยกรรมหน้าท้อง ดึงหน้า ยกกระชับ เอาซิลิโคนหรือสิ่งแปลกปลอมออก ศัลยกรรมแก้หน้าอก/สะโพก | AF7: 월 10:00 ~ 19:00 화 10:00 ~ 19:00 수 10:00 ~ 19:00 목 10:00 ~ 19:00 금 10:00 ~ 19:00 | AG7: 20300 | AH7: =AT7 -> 2.473 | AJ7: 4.5 | AK7: 8 | AM7: 36 | AN7: 0 | AO7: 0 | AP7: 3.8 | AQ7: 61 | AR7: 0 | AS7: =(AJ7*AK7)+(AL7*AM7)+(AN7*AO7)+(AP7*AQ7)/(AK7+AM7+AO7+AQ7) -> 2.5504762 | AT7: =IF( (AK7*IF(AK7<10,0.5,IF(AK7>=1000,10,IF(AK7>=500,5,IF(AK7>=100,2,1))))) + (AM7*IF(AM7<10,0.5,IF(AM7>=1000,10,IF(AM7>=500,5,IF(AM7>=100,2,1))))) + (AO7*IF(AO7<10,0.5,IF(AO7>=1000,10,IF(AO7>=500,5,IF(AO7>=100,2,1))))) + (AQ7*IF(AQ7<10,0.5,IF(AQ7>=1000,10,IF(AQ7>=500,5,IF(AQ7>=100,2,1))))) =0, "", ROUND( MIN(5, MAX(0, ( AJ7*(AK7*IF(AK7<10,0.5,IF(AK7>=1000,10,IF(AK7>=500,5,IF(AK7>=100,2,1))))) + AL7*(AM7*IF(AM7<10,0.5,IF(AM7>=1000,10,IF(AM7>=500,5,IF(AM7>=100,2,1))))) + AN7*(AO7*IF(AO7<10,0.5,IF(AO7>=1000,10,IF(AO7>=500,5,IF(AO7>=100,2,1))))) + AP7*(AQ7*IF(AQ7<10,0.5,IF(AQ7>=1000,10,IF(AQ7>=500,5,IF(AQ7>=100,2,1))))) ) / ( (AK7*IF(AK7<10,0.5,IF(AK7>=1000,10,IF(AK7>=500,5,IF(AK7>=100,2,1))))) + (AM7*IF(AM7<10,0.5,IF(AM7>=1000,10,IF(AM7>=500,5,IF(AM7>=100,2,1))))) + (AO7*IF(AO7<10,0.5,IF(AO7>=1000,10,IF(AO7>=500,5,IF(AO7>=100,2,1))))) + (AQ7*IF(AQ7<10,0.5,IF(AQ7>=1000,10,IF(AQ7>=500,5,IF(AQ7>=100,2,1))))) ) ) ), 3 ) ) -> 2.473
A8: 6 | B8: O | C8: 7 | D8: 4.5 | E8: =SUM( COUNTIF('리뷰 전체 모음 시트'!H:H, P8) ) -> 23 | F8: O | G8: O | H8: O | I8: △ | J8: O | K8: O | L8: O | M8: =COUNTIFS('의사 등록'!D:D, P8, '의사 등록'!E:E, "<>") -> 7 | N8: =COUNTIFS('의사 등록'!D:D, P8, '의사 등록'!T:T, "<>") -> 7 | O8: 리프팅 | P8: V&MJ피부과의원 | Q8: V&MJ Dermatology | R8: V&MJ คลินิกผิวหนัง | S8: 서울 강남구 신사동 | T8: Sinsa-dong, Gangnam-gu, Seoul | U8: แขวงซินซา เขตคังนัม กรุงโซล | V8: 37.522039 | W8: 127.03473 | X8: 서울 강남구 도산대로 303 | Y8: 303 Dosan-daero, Gangnam-gu, Seoul | Z8: 303 Dosan-daero, Gangnam-gu, Seoul | AB8: 기대가 현실이 되는 당신만을 위한 뷰티파라다이스 V&MJ 피부과 성형외과 입니다. V&MJ 피부과 성형외과는 피부만을 연구해온 전문 의료진과 해부학적 지식이 높은 성형외과 전문의의 풍부한 임상경험과 고객만을 생각하는 서비스를 통해 개개인의 아름다움을 이끌어냅니다. 그 어느병원에서도 경험하지 못한 커스터마이징이 당신을 찾아갑니다. | AC8: Welcome to V&MJ Dermatology & Plastic Surgery, your personal beauty paradise where expectations become reality. At V&MJ, our team of dermatology experts and plastic surgeons with deep anatomical knowledge and extensive clinical experience are dedicated to enhancing your natural beauty through personalized, patient-focused care. Experience a level of customization and service that you won’t find anywhere else. | AD8: ขอต้อนรับสู่ V&MJ คลินิกผิวหนังและศัลยกรรมตกแต่ง พาราไดซ์แห่งความงามที่ทำให้ความคาดหวังของคุณกลายเป็นจริง ที่ V&MJ ทีมแพทย์ผู้เชี่ยวชาญด้านผิวหนังและศัลยแพทย์ตกแต่งที่มีความรู้ด้านกายวิภาคอย่างลึกซึ้งและประสบการณ์ทางคลินิกมากมาย พร้อมดูแลและดึงความงามเฉพาะตัวของคุณออกมาด้วยบริการที่ใส่ใจในทุกรายละเอียด สัมผัสประสบการณ์การปรับแต่งเฉพาะบุคคลที่ไม่สามารถหาได้จากที่ใดมาก่อน | AF8: 월 10:00 ~ 19:00 화 10:00 ~ 19:00 수 10:00 ~ 19:00 목 10:00 ~ 19:00 금 10:00 ~ 21:00 토 10:00 ~ 16:00 | AG8: 800 | AH8: =AT8 -> 4.4 | AJ8: 4.8 | AK8: 95 | AL8: 4.4 | AM8: 1290 | AN8: 0 | AO8: 0 | AP8: 4 | AQ8: 95 | AR8: 85 | AS8: =(AJ8*AK8)+(AL8*AM8)+(AN8*AO8)+(AP8*AQ8)/(AK8+AM8+AO8+AQ8) -> 4.4 | AT8: =IF( (AK8*IF(AK8<10,0.5,IF(AK8>=1000,10,IF(AK8>=500,5,IF(AK8>=100,2,1))))) + (AM8*IF(AM8<10,0.5,IF(AM8>=1000,10,IF(AM8>=500,5,IF(AM8>=100,2,1))))) + (AO8*IF(AO8<10,0.5,IF(AO8>=1000,10,IF(AO8>=500,5,IF(AO8>=100,2,1))))) + (AQ8*IF(AQ8<10,0.5,IF(AQ8>=1000,10,IF(AQ8>=500,5,IF(AQ8>=100,2,1))))) =0, "", ROUND( MIN(5, MAX(0, ( AJ8*(AK8*IF(AK8<10,0.5,IF(AK8>=1000,10,IF(AK8>=500,5,IF(AK8>=100,2,1))))) + AL8*(AM8*IF(AM8<10,0.5,IF(AM8>=1000,10,IF(AM8>=500,5,IF(AM8>=100,2,1))))) + AN8*(AO8*IF(AO8<10,0.5,IF(AO8>=1000,10,IF(AO8>=500,5,IF(AO8>=100,2,1))))) + AP8*(AQ8*IF(AQ8<10,0.5,IF(AQ8>=1000,10,IF(AQ8>=500,5,IF(AQ8>=100,2,1))))) ) / ( (AK8*IF(AK8<10,0.5,IF(AK8>=1000,10,IF(AK8>=500,5,IF(AK8>=100,2,1))))) + (AM8*IF(AM8<10,0.5,IF(AM8>=1000,10,IF(AM8>=500,5,IF(AM8>=100,2,1))))) + (AO8*IF(AO8<10,0.5,IF(AO8>=1000,10,IF(AO8>=500,5,IF(AO8>=100,2,1))))) + (AQ8*IF(AQ8<10,0.5,IF(AQ8>=1000,10,IF(AQ8>=500,5,IF(AQ8>=100,2,1))))) ) ) ), 3 ) ) -> 4.4
A9: 7 | B9: O | C9: 8 | D9: 5 | E9: =SUM( COUNTIF('리뷰 전체 모음 시트'!H:H, P9) ) -> 33 | F9: O | G9: O | H9: O | I9: O | J9: O | K9: O | L9: O | M9: =COUNTIFS('의사 등록'!D:D, P9, '의사 등록'!E:E, "<>") -> 3 | N9: =COUNTIFS('의사 등록'!D:D, P9, '의사 등록'!T:T, "<>") -> 3 | O9: 눈, 코 | P9: 땡큐성형외과의원 | Q9: Thank You Plastic surgery | R9: แทงก์ยูคลินิกศัลยกรรมตกแต่ง | S9: 서울 강남구 역삼동 | T9: Yeoksam-dong, Gangnam-gu, Seoul | U9: แขวงย็อกซัม เขตคังนัม กรุงโซล | V9: 37.502487 | W9: 127.02602 | X9: 서울 강남구 역삼동 814-1 | Y9: 446 Gangnam-daero, Gangnam-gu, Seoul | Z9: 446 Gangnam-daero, Gangnam-gu, Seoul | AB9: THANK YOU Plastic Surgery 안전 중심 플랜 , 나를 아끼는 고마움 풍부한 임상 경험과 연구를 바탕으로 과잉 진료 없이 환자에게 어울리는 최고의 아름다움을 선물합니다🧑🏻‍⚕️ ✔️풍부한 경험을 가진 각 분야 전담 의료진 직접 상담 및 수술 ✔️ 고객의 안전을 최우선시 하는 대학 병원급 안전 관리 시스템 ✔️만족도 높은 수술 결과를 위한 체계적인 수술 후 관리 시스템 ✔️ 대리수술 0% , 수술 실명제 실시 오직 당신만을 위한 땡큐 뷰티철학🍀 | AC9: THANK YOU Plastic Surgery — a safety-centered plan and the value of self-appreciation. Based on extensive clinical experience and research, we provide patients with the most suitable beauty without unnecessary treatments. 🧑🏻‍⚕️✔️ Direct consultation and surgery by dedicated specialists with abundant experience in each field ✔️ University hospital–level safety management system prioritizing patient safety ✔️ Systematic postoperative care for highly satisfying surgical results ✔️ Zero proxy surgery, with a real-name surgery system in place Only for you — the Thank You beauty philosophy. 🍀 | AD9: THANK YOU Plastic Surgery — แผนการรักษาที่มุ่งเน้นความปลอดภัยและคุณค่าของการเห็นคุณค่าในตัวเอง โดยอาศัยประสบการณ์ทางคลินิกและงานวิจัยที่หลากหลาย เรามอบความงามที่เหมาะสมที่สุดแก่ผู้ป่วยโดยไม่ทำการรักษาเกินความจำเป็น 🧑🏻‍⚕️ ✔️ ปรึกษาและผ่าตัดโดยแพทย์ผู้เชี่ยวชาญเฉพาะด้านที่มีประสบการณ์สูง ✔️ ระบบการจัดการความปลอดภัยระดับโรงพยาบาลมหาวิทยาลัย ที่ให้ความสำคัญกับความปลอดภัยของผู้ป่วยเป็นอันดับแรก ✔️ ระบบการดูแลหลังการผ่าตัดอย่างเป็นระบบ เพื่อผลลัพธ์ที่น่าพึงพอใจ ✔️ ไม่มีการผ่าตัดแทน (0%) พร้อมระบบระบุชื่อศัลยแพทย์ที่ชัดเจน ปรัชญาความงามของ Thank You — มีไว้เพื่อคุณคนเดียว 🍀 | AF9: {"friday":{"openTime":"2025-04-01T01:00:00.000Z","closeTime":"2025-04-01T10:00:00.000Z","monday":{"openTime":"2025-04-01T01:00:00.000Z","closeTime":"2025-04-01T10:00:00.000Z","sunday":{"holiday":true,"tuesday":{"openTime":"2025-04-01T01:00:00.000Z","closeTime":"2025-04-01T10:00:00.000Z","saturday":{"openTime":"2025-04-01T01:00:00.000Z","closeTime":"2025-04-01T07:00:00.000Z","thursday":{"openTime":"2025-04-01T01:00:00.000Z","closeTime":"2025-04-01T10:00:00.000Z","wednesday":{"openTime":"2025-04-01T01:00:00.000Z","closeTime":"2025-04-01T10:00:00.000Z" | AG9: 1620 | AH9: =AT9 -> 4.226 | AJ9: 4.9 | AK9: 823 | AM9: 267 | AN9: 4.5 | AO9: 82 | AP9: 4.1 | AQ9: 856 | AR9: 85 | AS9: =(AJ9*AK9)+(AL9*AM9)+(AN9*AO9)+(AP9*AQ9)/(AK9+AM9+AO9+AQ9) -> 3.9010355 | AT9: =IF( (AK9*IF(AK9<10,0.5,IF(AK9>=1000,10,IF(AK9>=500,5,IF(AK9>=100,2,1))))) + (AM9*IF(AM9<10,0.5,IF(AM9>=1000,10,IF(AM9>=500,5,IF(AM9>=100,2,1))))) + (AO9*IF(AO9<10,0.5,IF(AO9>=1000,10,IF(AO9>=500,5,IF(AO9>=100,2,1))))) + (AQ9*IF(AQ9<10,0.5,IF(AQ9>=1000,10,IF(AQ9>=500,5,IF(AQ9>=100,2,1))))) =0, "", ROUND( MIN(5, MAX(0, ( AJ9*(AK9*IF(AK9<10,0.5,IF(AK9>=1000,10,IF(AK9>=500,5,IF(AK9>=100,2,1))))) + AL9*(AM9*IF(AM9<10,0.5,IF(AM9>=1000,10,IF(AM9>=500,5,IF(AM9>=100,2,1))))) + AN9*(AO9*IF(AO9<10,0.5,IF(AO9>=1000,10,IF(AO9>=500,5,IF(AO9>=100,2,1))))) + AP9*(AQ9*IF(AQ9<10,0.5,IF(AQ9>=1000,10,IF(AQ9>=500,5,IF(AQ9>=100,2,1))))) ) / ( (AK9*IF(AK9<10,0.5,IF(AK9>=1000,10,IF(AK9>=500,5,IF(AK9>=100,2,1))))) + (AM9*IF(AM9<10,0.5,IF(AM9>=1000,10,IF(AM9>=500,5,IF(AM9>=100,2,1))))) + (AO9*IF(AO9<10,0.5,IF(AO9>=1000,10,IF(AO9>=500,5,IF(AO9>=100,2,1))))) + (AQ9*IF(AQ9<10,0.5,IF(AQ9>=1000,10,IF(AQ9>=500,5,IF(AQ9>=100,2,1))))) ) ) ), 3 ) ) -> 4.226 | AV9: APPROVED | AY9: FALSE | AZ9: 32e88b22-9200-4190-8656-08ad07df140c | BA9: 45748.284 | BB9: 45856.251
A10: 8 | B10: O | C10: 9 | D10: 4.9 | E10: =SUM( COUNTIF('리뷰 전체 모음 시트'!H:H, P10) ) -> 15 | F10: O | G10: O | H10: O | I10: △ | J10: O | K10: O | L10: O | M10: =COUNTIFS('의사 등록'!D:D, P10, '의사 등록'!E:E, "<>") -> 1 | N10: =COUNTIFS('의사 등록'!D:D, P10, '의사 등록'!T:T, "<>") -> 1 | O10: 눈, 리프팅 | P10: 연세다인성형외과의원 | Q10: YONSEI DAIN Plastic Surgery | R10: YONSEI DAIN คลินิกศัลยกรรมตกแต่ง | S10: 서울 강남구 신사동 | T10: Sinsa-dong, Gangnam-gu, Seoul | U10: แขวงซินซา เขตคังนัม กรุงโซล | V10: 37.524808 | W10: 127.02783 | X10: 서울 강남구 압구정로28길 25 동심빌딩 3층 | Y10: 25 Apgujeong-ro 28-gil, Gangnam-gu, Seoul | Z10: 25 Apgujeong-ro 28-gil, Gangnam-gu, Seoul | AB10: 안전하고 고객만족 중심의 가치를 높이는 시술을 합니다. 연세다인성형외과가 당신의 아름다움의 기준이 됩니다. | AC10: We provide procedures that prioritize safety and enhance customer satisfaction. Yonsei Dain Plastic Surgery sets the new standard of beauty for you. | AD10: เรามุ่งเน้นการทำหัตถการที่ปลอดภัยและมอบความพึงพอใจสูงสุดให้กับลูกค้า Yonsei Dain คลินิกศัลยกรรมตกแต่ง คือมาตรฐานใหม่แห่งความงามสำหรับคุณ | AF10: 월 10:00 ~ 18:30 화 10:00 ~ 18:30 수 10:00 ~ 18:30 목 10:00 ~ 18:30 금 10:00 ~ 18:30 토 10:00 ~ 15:00 | AG10: 가격 명시X (1500) | AH10: =AT10 -> 2.032 | AJ10: 5 | AK10: 3 | AL10: 0 | AM10: 27 | AN10: 0 | AO10: 0 | AP10: 3.9 | AQ10: 27 | AR10: 84 | AS10: =(AJ10*AK10)+(AL10*AM10)+(AN10*AO10)+(AP10*AQ10)/(AK10+AM10+AO10+AQ10) -> 2.1105263 | AT10: =IF( (AK10*IF(AK10<10,0.5,IF(AK10>=1000,10,IF(AK10>=500,5,IF(AK10>=100,2,1))))) + (AM10*IF(AM10<10,0.5,IF(AM10>=1000,10,IF(AM10>=500,5,IF(AM10>=100,2,1))))) + (AO10*IF(AO10<10,0.5,IF(AO10>=1000,10,IF(AO10>=500,5,IF(AO10>=100,2,1))))) + (AQ10*IF(AQ10<10,0.5,IF(AQ10>=1000,10,IF(AQ10>=500,5,IF(AQ10>=100,2,1))))) =0, "", ROUND( MIN(5, MAX(0, ( AJ10*(AK10*IF(AK10<10,0.5,IF(AK10>=1000,10,IF(AK10>=500,5,IF(AK10>=100,2,1))))) + AL10*(AM10*IF(AM10<10,0.5,IF(AM10>=1000,10,IF(AM10>=500,5,IF(AM10>=100,2,1))))) + AN10*(AO10*IF(AO10<10,0.5,IF(AO10>=1000,10,IF(AO10>=500,5,IF(AO10>=100,2,1))))) + AP10*(AQ10*IF(AQ10<10,0.5,IF(AQ10>=1000,10,IF(AQ10>=500,5,IF(AQ10>=100,2,1))))) ) / ( (AK10*IF(AK10<10,0.5,IF(AK10>=1000,10,IF(AK10>=500,5,IF(AK10>=100,2,1))))) + (AM10*IF(AM10<10,0.5,IF(AM10>=1000,10,IF(AM10>=500,5,IF(AM10>=100,2,1))))) + (AO10*IF(AO10<10,0.5,IF(AO10>=1000,10,IF(AO10>=500,5,IF(AO10>=100,2,1))))) + (AQ10*IF(AQ10<10,0.5,IF(AQ10>=1000,10,IF(AQ10>=500,5,IF(AQ10>=100,2,1))))) ) ) ), 3 ) ) -> 2.032
A11: 9 | B11: O | C11: 10 | D11: 4.8 | E11: =SUM( COUNTIF('리뷰 전체 모음 시트'!H:H, P11) ) -> 23 | F11: O | G11: O | H11: O | I11: O | J11: O | K11: O | L11: O | M11: =COUNTIFS('의사 등록'!D:D, P11, '의사 등록'!E:E, "<>") -> 2 | N11: =COUNTIFS('의사 등록'!D:D, P11, '의사 등록'!T:T, "<>") -> 2 | O11: 바디 | P11: 허쉬성형외과의원 | Q11: HERSHE Plastic Surgery | R11: คลินิกศัลยกรรมตกแต่งเฮอชี | S11: 서울 강남구 청담동 | T11: Cheongdam-dong, Gangnam-gu, Seoul | U11: แขวงชองดัม เขตคังนัม กรุงโซล | V11: 37.52099 | W11: 127.04945 | X11: 서울 강남구 삼성로 730 2~4층 | Y11: 730 Samseong-ro, Gangnam-gu, Seoul | Z11: 730 Samseong-ro, Gangnam-gu, Seoul | AB11: 1992년 설립이래 지금까지 수많은 고객과 함께해 온 허쉬성형외과는 ‘자연스러움’이라는 가치를 최우선으로 생각하며, 각 분야별 전담 의료진의 깊이 있는 전문성과 오랜 임상 경험, 그리고 혁신적인 접근을 바탕으로 정교하고 안정적인 시술을 제공합니다. 안정적인 의료 서비스를 제공해 온 공로를 인정받아 보건복지부장관상을 수상한 바 있습니다. | AC11: Since its establishment in 1992, HERSHE Plastic Surgery Clinic has walked alongside countless clients, valuing “natural beauty” as its top priority. With a team of specialized medical professionals in each field, deep expertise, extensive clinical experience, and an innovative approach, HERSHE provides precise and reliable treatments. In recognition of its excellence and contribution to safe medical service, the clinic was honored with the Minister of Health and Welfare Award. | AD11: ตั้งแต่ก่อตั้งขึ้นในปี ค.ศ. 1992 HERSHE Plastic Surgery Clinic ได้ดูแลลูกค้ามากมายโดยยึดถือ “ความงามอย่างเป็นธรรมชาติ” เป็นคุณค่าที่สำคัญที่สุด ทีมแพทย์ผู้เชี่ยวชาญเฉพาะทางแต่ละสาขามีความรู้ลึกซึ้ง ประสบการณ์ทางคลินิกยาวนาน และแนวทางที่เป็นนวัตกรรม จึงสามารถมอบการรักษาที่ละเอียดและปลอดภัยได้อย่างมั่นใจ ทั้งนี้คลินิกได้รับ รางวัลเกียรติคุณจากรัฐมนตรีว่าการกระทรวงสาธารณสุขเกาหลี เพื่อยกย่องในความเป็นเลิศด้านบริการทางการแพทย์ที่ปลอดภัย | AF11: 월 10:00 ~ 19:00 화 10:00 ~ 19:00 수 10:00 ~ 19:00 목 10:00 ~ 19:00 금 10:00 ~ 19:00 토 10:00 ~ 16:00 | AG11: 2700 | AH11: =AT11 -> 1.82 | AJ11: 5 | AK11: 42 | AL11: 0 | AM11: 157 | AN11: 0 | AO11: 0 | AP11: 3.6 | AQ11: 123 | AR11: 74 | AS11: =(AJ11*AK11)+(AL11*AM11)+(AN11*AO11)+(AP11*AQ11)/(AK11+AM11+AO11+AQ11) -> 2.0273292 | AT11: =IF( (AK11*IF(AK11<10,0.5,IF(AK11>=1000,10,IF(AK11>=500,5,IF(AK11>=100,2,1))))) + (AM11*IF(AM11<10,0.5,IF(AM11>=1000,10,IF(AM11>=500,5,IF(AM11>=100,2,1))))) + (AO11*IF(AO11<10,0.5,IF(AO11>=1000,10,IF(AO11>=500,5,IF(AO11>=100,2,1))))) + (AQ11*IF(AQ11<10,0.5,IF(AQ11>=1000,10,IF(AQ11>=500,5,IF(AQ11>=100,2,1))))) =0, "", ROUND( MIN(5, MAX(0, ( AJ11*(AK11*IF(AK11<10,0.5,IF(AK11>=1000,10,IF(AK11>=500,5,IF(AK11>=100,2,1))))) + AL11*(AM11*IF(AM11<10,0.5,IF(AM11>=1000,10,IF(AM11>=500,5,IF(AM11>=100,2,1))))) + AN11*(AO11*IF(AO11<10,0.5,IF(AO11>=1000,10,IF(AO11>=500,5,IF(AO11>=100,2,1))))) + AP11*(AQ11*IF(AQ11<10,0.5,IF(AQ11>=1000,10,IF(AQ11>=500,5,IF(AQ11>=100,2,1))))) ) / ( (AK11*IF(AK11<10,0.5,IF(AK11>=1000,10,IF(AK11>=500,5,IF(AK11>=100,2,1))))) + (AM11*IF(AM11<10,0.5,IF(AM11>=1000,10,IF(AM11>=500,5,IF(AM11>=100,2,1))))) + (AO11*IF(AO11<10,0.5,IF(AO11>=1000,10,IF(AO11>=500,5,IF(AO11>=100,2,1))))) + (AQ11*IF(AQ11<10,0.5,IF(AQ11>=1000,10,IF(AQ11>=500,5,IF(AQ11>=100,2,1))))) ) ) ), 3 ) ) -> 1.82
A12: 10 | B12: O | C12: 11 | D12: 4.7 | E12: =SUM( COUNTIF('리뷰 전체 모음 시트'!H:H, P12) ) -> 23 | F12: O | G12: O | H12: O | I12: O | J12: O | K12: O | L12: O | M12: =COUNTIFS('의사 등록'!D:D, P12, '의사 등록'!E:E, "<>") -> 4 | N12: =COUNTIFS('의사 등록'!D:D, P12, '의사 등록'!T:T, "<>") -> 4 | O12: 바디 | P12: 플랜에스의원 | Q12: Plan S Clinic | R12: Plan S คลินิก | S12: 서울 강남구 역삼동 | T12: Yeoksam-dong, Gangnam-gu, Seoul | U12: แขวงย็อกซัม เขตคังนัม กรุงโซล | V12: 37.499214 | W12: 127.02747 | X12: 서울 강남구 강남대로 408 YBM강남센터 B1, 2층 | Y12: 408 Gangnam-daero, Gangnam-gu, Seoul | Z12: 408 Gangnam-daero, Gangnam-gu, Seoul | AB12: 라인을 찾는 공간, 플랜에스의원 다이어트·리프팅 중점 진료 | AC12: A place to discover your perfect line — Plan S Clinic, specializing in diet and lifting treatments. | AD12: พื้นที่สำหรับค้นหาเส้นสวยในแบบของคุณ — Plan S คลินิกผู้เชี่ยวชาญด้านการลดน้ำหนักและการยกกระชับ | AF12: 월 10:30 ~ 20:00 화 10:30 ~ 20:00 수 10:30 ~ 20:00 목 10:30 ~ 20:00 금 10:30 ~ 20:00 토 10:30 ~ 16:00 | AG12: 800 | AH12: =AT12 -> 2.964 | AJ12: 4.9 | AK12: 1853 | AM12: 1210 | AN12: 0 | AO12: 0 | AP12: 4 | AQ12: 7 | AR12: 0 | AS12: =(AJ12*AK12)+(AL12*AM12)+(AN12*AO12)+(AP12*AQ12)/(AK12+AM12+AO12+AQ12) -> 2.9666775 | AT12: =IF( (AK12*IF(AK12<10,0.5,IF(AK12>=1000,10,IF(AK12>=500,5,IF(AK12>=100,2,1))))) + (AM12*IF(AM12<10,0.5,IF(AM12>=1000,10,IF(AM12>=500,5,IF(AM12>=100,2,1))))) + (AO12*IF(AO12<10,0.5,IF(AO12>=1000,10,IF(AO12>=500,5,IF(AO12>=100,2,1))))) + (AQ12*IF(AQ12<10,0.5,IF(AQ12>=1000,10,IF(AQ12>=500,5,IF(AQ12>=100,2,1))))) =0, "", ROUND( MIN(5, MAX(0, ( AJ12*(AK12*IF(AK12<10,0.5,IF(AK12>=1000,10,IF(AK12>=500,5,IF(AK12>=100,2,1))))) + AL12*(AM12*IF(AM12<10,0.5,IF(AM12>=1000,10,IF(AM12>=500,5,IF(AM12>=100,2,1))))) + AN12*(AO12*IF(AO12<10,0.5,IF(AO12>=1000,10,IF(AO12>=500,5,IF(AO12>=100,2,1))))) + AP12*(AQ12*IF(AQ12<10,0.5,IF(AQ12>=1000,10,IF(AQ12>=500,5,IF(AQ12>=100,2,1))))) ) / ( (AK12*IF(AK12<10,0.5,IF(AK12>=1000,10,IF(AK12>=500,5,IF(AK12>=100,2,1))))) + (AM12*IF(AM12<10,0.5,IF(AM12>=1000,10,IF(AM12>=500,5,IF(AM12>=100,2,1))))) + (AO12*IF(AO12<10,0.5,IF(AO12>=1000,10,IF(AO12>=500,5,IF(AO12>=100,2,1))))) + (AQ12*IF(AQ12<10,0.5,IF(AQ12>=1000,10,IF(AQ12>=500,5,IF(AQ12>=100,2,1))))) ) ) ), 3 ) ) -> 2.964
A13: 11 | B13: O | C13: 12 | D13: 4.6 | E13: =SUM( COUNTIF('리뷰 전체 모음 시트'!H:H, P13) ) -> 23 | F13: O | G13: O | H13: O | I13: O | J13: O | K13: O | L13: O | M13: =COUNTIFS('의사 등록'!D:D, P13, '의사 등록'!E:E, "<>") -> 4 | N13: =COUNTIFS('의사 등록'!D:D, P13, '의사 등록'!T:T, "<>") -> 4 | O13: 안면윤곽 | P13: 일퍼센트성형외과의원 | Q13: 1% One Percent Plastic Surgery | R13: 1% ศัลยกรรมตกแต่งหนึ่งเปอร์เซ็นต์ | S13: 서울 강남구 논현동 | T13: Nonhyeon-dong, Gangnam-gu, Seoul | U13: แขวงนอนฮยอน เขตคังนัม กรุงโซล | V13: 37.51748 | W13: 127.02375 | X13: 서울 강남구 도산대로 138 (논현동) 7,8층 | Y13: 7F, 8F 138 Dosan-daero, Gangnam-gu, Seoul | Z13: 7F, 8F 138 Dosan-daero, Gangnam-gu, Seoul | AB13: 1%의 디테일이 수술결과와 만족감을 좌우한다는 것 일퍼센트는 그 1%를 지키고자 합니다 | AC13: 1% of detail determines surgical results and satisfaction. Ilpercent strives to preserve that 1%. | AD13: รายละเอียด 1% เป็นตัวกำหนดผลลัพธ์และความพึงพอใจในการผ่าตัด Ilpercent มุ่งมั่นที่จะรักษารายละเอียด 1% นี้ไว้ | AF13: 월 10:00~19:00 화 10:00~19:00 수 10:00~19:00 목 10:00~19:00 금 10:00~21:00 토 10:00~16:00 | AG13: 8700 | AH13: =AT13 -> 1.972 | AJ13: 4.4 | AK13: 9 | AM13: 300 | AP13: 3.9 | AQ13: 304 | AR13: 79 | AS13: =(AJ13*AK13)+(AL13*AM13)+(AN13*AO13)+(AP13*AQ13)/(AK13+AM13+AO13+AQ13) -> 1.9986949 | AT13: =IF( (AK13*IF(AK13<10,0.5,IF(AK13>=1000,10,IF(AK13>=500,5,IF(AK13>=100,2,1))))) + (AM13*IF(AM13<10,0.5,IF(AM13>=1000,10,IF(AM13>=500,5,IF(AM13>=100,2,1))))) + (AO13*IF(AO13<10,0.5,IF(AO13>=1000,10,IF(AO13>=500,5,IF(AO13>=100,2,1))))) + (AQ13*IF(AQ13<10,0.5,IF(AQ13>=1000,10,IF(AQ13>=500,5,IF(AQ13>=100,2,1))))) =0, "", ROUND( MIN(5, MAX(0, ( AJ13*(AK13*IF(AK13<10,0.5,IF(AK13>=1000,10,IF(AK13>=500,5,IF(AK13>=100,2,1))))) + AL13*(AM13*IF(AM13<10,0.5,IF(AM13>=1000,10,IF(AM13>=500,5,IF(AM13>=100,2,1))))) + AN13*(AO13*IF(AO13<10,0.5,IF(AO13>=1000,10,IF(AO13>=500,5,IF(AO13>=100,2,1))))) + AP13*(AQ13*IF(AQ13<10,0.5,IF(AQ13>=1000,10,IF(AQ13>=500,5,IF(AQ13>=100,2,1))))) ) / ( (AK13*IF(AK13<10,0.5,IF(AK13>=1000,10,IF(AK13>=500,5,IF(AK13>=100,2,1))))) + (AM13*IF(AM13<10,0.5,IF(AM13>=1000,10,IF(AM13>=500,5,IF(AM13>=100,2,1))))) + (AO13*IF(AO13<10,0.5,IF(AO13>=1000,10,IF(AO13>=500,5,IF(AO13>=100,2,1))))) + (AQ13*IF(AQ13<10,0.5,IF(AQ13>=1000,10,IF(AQ13>=500,5,IF(AQ13>=100,2,1))))) ) ) ), 3 ) ) -> 1.972
A14: 12 | B14: O | C14: 13 | D14: 4.5 | E14: =SUM( COUNTIF('리뷰 전체 모음 시트'!H:H, P14) ) -> 23 | F14: O | G14: O | H14: O | I14: O | J14: O | K14: O | L14: O | M14: =COUNTIFS('의사 등록'!D:D, P14, '의사 등록'!E:E, "<>") -> 1 | N14: =COUNTIFS('의사 등록'!D:D, P14, '의사 등록'!T:T, "<>") -> 1 | O14: 눈 | P14: 슈가성형외과의원 | Q14: SUGAR Plastic Surgery | R14: SUGAR คลินิกศัลยกรรมตกแต่ง | S14: 서울 서초구 서초동 | T14: Seocho-dong, Seocho-gu, Seoul | U14: แขวงซอชโช เขตซอชโช กรุงโซล | V14: 37.50342 | W14: 127.02447 | X14: 서울 서초구 강남대로 463 8층 | Y14: 463 Gangnam-daero, Seocho-gu, Seoul | Z14: 463 Gangnam-daero, Seocho-gu, Seoul | AB14: 슈가성형외과는 개인별 맞춤 성형으로 만족스러운 결과를 위해 항상 노력하고 있습니다. 고객 한명의 첫 방문부터 회복까지 전문의와의 편안한 동행이 계속됩니다. 진실성 있는 진료로 필요한 수술만을 권하고 보다 나은 결과로 고객이 행복할 수 있도록 노력합니다. 최신 수술 시스템으로 첫 만남과 마지막 만남이 유쾌할 수 있도록 노력합니다. | AC14: Suga Plastic Surgery is dedicated to providing personalized procedures tailored to each individual for the most satisfying results. From the very first visit to full recovery, our board-certified specialists accompany every patient with comfort and care. With honesty and integrity, we recommend only the procedures that are truly necessary and strive to deliver results that bring genuine happiness to our clients. Using the latest surgical systems, we aim to make both your first and final visit a pleasant and reassuring experience. | AD14: คลินิกศัลยกรรม Suga Plastic Surgery มุ่งมั่นในการให้บริการศัลยกรรมแบบ เฉพาะบุคคล เพื่อผลลัพธ์ที่น่าพึงพอใจที่สุดสำหรับคนไข้แต่ละราย ตั้งแต่การเข้ารับคำปรึกษาครั้งแรกจนถึงช่วงพักฟื้น คุณหมอผู้เชี่ยวชาญจะดูแลอย่างใกล้ชิดตลอดทุกขั้นตอน เรายึดมั่นในความซื่อสัตย์ แนะนำเฉพาะการผ่าตัดที่จำเป็นจริง ๆ และมุ่งมั่นให้ผลลัพธ์ที่ทำให้ผู้รับบริการมีความสุขที่สุด ด้วย เทคโนโลยีการผ่าตัดที่ทันสมัย เราพยายามให้ทุกการพบกันตั้งแต่ครั้งแรกจนถึงครั้งสุดท้ายเป็นประสบการณ์ที่ดีและน่าประทับใจ | AF14: 월 10:00 ~ 19:00 화 10:00 ~ 19:00 수 10:00 ~ 19:00 목 10:00 ~ 19:00 금 10:00 ~ 19:00 토 10:00 ~ 16:00 | AG14: 1900 | AH14: =AT14 -> 3.754 | AJ14: 5 | AK14: 80 | AL14: 0 | AM14: 58 | AN14: 4.1 | AO14: 14 | AP14: 4.2 | AQ14: 127 | AR14: 73 | AS14: =(AJ14*AK14)+(AL14*AM14)+(AN14*AO14)+(AP14*AQ14)/(AK14+AM14+AO14+AQ14) -> 3.5512545 | AT14: =IF( (AK14*IF(AK14<10,0.5,IF(AK14>=1000,10,IF(AK14>=500,5,IF(AK14>=100,2,1))))) + (AM14*IF(AM14<10,0.5,IF(AM14>=1000,10,IF(AM14>=500,5,IF(AM14>=100,2,1))))) + (AO14*IF(AO14<10,0.5,IF(AO14>=1000,10,IF(AO14>=500,5,IF(AO14>=100,2,1))))) + (AQ14*IF(AQ14<10,0.5,IF(AQ14>=1000,10,IF(AQ14>=500,5,IF(AQ14>=100,2,1))))) =0, "", ROUND( MIN(5, MAX(0, ( AJ14*(AK14*IF(AK14<10,0.5,IF(AK14>=1000,10,IF(AK14>=500,5,IF(AK14>=100,2,1))))) + AL14*(AM14*IF(AM14<10,0.5,IF(AM14>=1000,10,IF(AM14>=500,5,IF(AM14>=100,2,1))))) + AN14*(AO14*IF(AO14<10,0.5,IF(AO14>=1000,10,IF(AO14>=500,5,IF(AO14>=100,2,1))))) + AP14*(AQ14*IF(AQ14<10,0.5,IF(AQ14>=1000,10,IF(AQ14>=500,5,IF(AQ14>=100,2,1))))) ) / ( (AK14*IF(AK14<10,0.5,IF(AK14>=1000,10,IF(AK14>=500,5,IF(AK14>=100,2,1))))) + (AM14*IF(AM14<10,0.5,IF(AM14>=1000,10,IF(AM14>=500,5,IF(AM14>=100,2,1))))) + (AO14*IF(AO14<10,0.5,IF(AO14>=1000,10,IF(AO14>=500,5,IF(AO14>=100,2,1))))) + (AQ14*IF(AQ14<10,0.5,IF(AQ14>=1000,10,IF(AQ14>=500,5,IF(AQ14>=100,2,1))))) ) ) ), 3 ) ) -> 3.754
